Workbook

Sheet 样品编号表
A1: 样品编号表 | S1: 胚布信息 | W1: 现货信息
A2: 序列号 | B2: *创建日期 Creative Date | C2: *业务员 Owner | D2: 客户 | E2: 项目当日编号 | F2: 材料名称 Name | G2: 布种类型 | H2: *布种编号 #Base | I2: 成份（中文) Composition | J2: *成份（英文） Composition | K2: *可裁门幅 Width | L2: *克重GSM | M2: *SPECIFICATION/规格 （经纱支x纬纱支） | N2: *SPECIFICATION/密度 （经密度x纬密度） | O2: 全部加工工艺（中文） Processes | P2: *全部加工工艺（英文） Processes | Q2: 备注（纱，组织，染整及功能特殊要求，指标等） Remark special yarn, weave, process, function,etc | R2: *塑胶类 厚度mm | S2: *胚布厂 Greige mill | T2: *胚布厂胚布编码 Greige #article | U2: *胚布采购价格RMB/M | W2: *一级供应商/mill | X2: *供应商编码/ #article | Y2: *二级供应商/mill | Z2: *供应商编码/ #article | AA2: *现货采购价格RMB/M | AB2: 报价日期 Date 年/月/日 | AC2: YDGE MOQ/Bulk MOQ 成品码样MOQ/成品大货MOQ | AD2: YDGE L/T/Bulk L/T 成品码样货期/成品大货货期 | AE2: YDGE Surcharge/Bulk Surcharge 成品码样费用/成品大货费用 | AF2: Stock available 成品是否有库存 | AG2: 小类别 | AH2: 备注 | AI2: 提供人员 | AJ2: 布料存放位置 | AK2: 数量 | AL2: 存放人员 | AM2: 是否已拍照
A3: 1 | B3: 45765 | C3: 陈炎林 | D3: GFG | E3: D18-1 | F3: 尚源纺织色卡或者类似 | H3: SC25001 | I3: 100%棉 | J3: 100%BCI COTTON | K3: 125 | O3: 染定 | P3: P/D | W3: 欧纺时尚 | X3: K321 | Y3: 尚源 | Z3: K321 | AG3: 小块样布 | AM3: 是
A4: 2 | B4: 45765 | C4: 陈炎林 | D4: GFG | F4: 新丰花边 | H4: SC25001-1 | I4: 100%棉 | J4: 100%BCI COTTON | K4: 125 | W4: 欧纺时尚 | X4: 花边 | Y4: 新丰花边 | Z4: 花边 | AG4: 小块样布 | AM4: 是
A5: 3 | B5: 45765 | C5: 陈炎林 | D5: GFG | F5: A-ONE | H5: SC25001-2 | I5: 100%棉 | J5: 100%BCI COTTON | K5: 125 | W5: 欧纺时尚 | X5: A-ONE | Y5: 欧纺时尚 | Z5: A-ONE | AG5: 小块样布 | AM5: 是
A6: 4 | B6: 45765 | C6: 陈炎林 | D6: GFG | F6: K321 | H6: SC25001-3 | I6: 100%棉 | J6: 100%BCI COTTON | K6: 125 | W6: 欧纺时尚 | X6: K321 | Y6: 欧纺时尚 | Z6: K321 | AA6: 13.2 | AB6: 45764 | AG6: 小块样布 | AM6: 是
A7: 5 | B7: 45765 | C7: 陈炎林 | D7: GFG | F7: 永成花边行李佩莲13424008907/许晓程13570899693 | H7: SC25001-4 | I7: 100%棉 | J7: 100%BCI COTTON | K7: 125 | W7: 欧纺时尚 | X7: 花边 | Y7: 永成花边行 | Z7: 花边 | AG7: 小块样布 | AM7: 是
A8: 6 | B8: 45765 | C8: 陈炎林 | D8: GFG | E8: D18-3 | F8: 花边1.5-2厘米有圈圈或格子 | H8: SC25002 | I8: 100%棉 | J8: 100%BCI COTTON | K8: 125 | O8: 染定 | P8: P/D | W8: 欧纺时尚 | X8: 1.5-2厘米圈圈或格子 | Y8: 欧纺时尚 | Z8: 1.5-2厘米圈圈或格子 | AG8: 小块样布 | AM8: 是
A9: 7 | B9: 45766 | C9: 陈炎林 | D9: GFG | F9: 瑞康3 楼C032 花边 | H9: SC25003 | I9: 100%棉 | J9: 100%BCI COTTON | K9: 125 | O9: 染定 | P9: P/D | W9: 欧纺时尚 | X9: 瑞康3 楼C032 花边 | Y9: 欧纺时尚 | Z9: 瑞康3 楼C032 花边 | AA9: 14.2 | AB9: 45766 | AG9: 小块样布 | AM9: 是
A10: 8 | B10: 45766 | C10: 陈炎林 | D10: GFG | F10: 刺绣/绣花 | H10: SC25004 | I10: 100%棉 | J10: 100%BCI COTTON | K10: 125 | O10: 染定 | P10: P/D | W10: 欧纺时尚 | X10: 刺绣/绣花 | Y10: 欧纺时尚 | Z10: 刺绣/绣花 | AG10: 小块样布 | AM10: 是
A11: 9 | B11: 45766 | C11: 陈炎林 | D11: GFG | F11: 刺绣/绣花-鑫隆8字花 | H11: SC25004-1 | I11: 100%棉 | J11: 100%BCI COTTON | K11: 125 | W11: 欧纺时尚 | X11: 8字花 | Y11: 鑫隆 | Z11: 8字花 | AG11: 小块样布 | AM11: 是
A12: 10 | B12: 45766 | C12: 陈炎林 | D12: GFG | F12: 刺绣/绣花-鑫隆578 | H12: SC25004-2 | I12: 100%棉 | J12: 100%BCI COTTON | K12: 125 | W12: 欧纺时尚 | X12: 578 | Y12: 鑫隆 | Z12: 578 | AG12: 小块样布 | AM12: 是
A13: 11 | B13: 45766 | C13: 陈炎林 | D13: GFG | F13: 刺绣/绣花-鑫隆A9065 | H13: SC25004-3 | I13: 100%棉 | J13: 100%BCI COTTON | K13: 125 | W13: 欧纺时尚 | X13: A9065 | Y13: 鑫隆 | Z13: A9065 | AG13: 小块样布 | AM13: 是
A14: 12 | B14: 45766 | C14: 陈炎林 | D14: GFG | F14: 刺绣/绣花-鑫隆双层太阳 | H14: SC25004-4 | I14: 100%棉 | J14: 100%BCI COTTON | K14: 125 | W14: 欧纺时尚 | X14: 双层太阳 | Y14: 鑫隆 | Z14: 双层太阳 | AG14: 小块样布 | AM14: 是
A15: 13 | B15: 45766 | C15: 陈炎林 | D15: GFG | F15: 刺绣/绣花-鑫隆C-5 | H15: SC25004-5 | I15: 100%棉 | J15: 100%BCI COTTON | K15: 125 | W15: 欧纺时尚 | X15: C-5 | Y15: 鑫隆 | Z15: C-5 | AG15: 小块样布 | AM15: 是
A16: 14 | B16: 45766 | C16: 陈炎林 | D16: GFG | F16: 刺绣/绣花-鑫隆C-1 | H16: SC25004-6 | I16: 100%棉 | J16: 100%BCI COTTON | K16: 125 | W16: 欧纺时尚 | X16: C-1 | Y16: 鑫隆 | Z16: C-1 | AG16: 小块样布 | AM16: 是
A17: 15 | B17: 45766 | C17: 陈炎林 | D17: GFG | F17: 永成花边行李佩莲13424008907/许晓程13570899693 | H17: SC25004-7 | I17: 100%棉 | J17: 100%BCI COTTON | K17: 125 | W17: 欧纺时尚 | Y17: 永成花边行李佩莲13424008907/许晓程13570899693 | AG17: 小块样布 | AM17: 是
A18: 16 | B18: 45769 | C18: 陈炎林 | D18: 永叙 | E18: D19-1 | F18: 67165 | H18: SC25005 | I18: 95%棉 5%氨纶 | J18: 95%COTTON 5%SP | K18: 140 | L18: 210 | O18: 染定 | P18: P/D | W18: 欧纺时尚 | X18: 67165 | Y18: 文涛布业 | Z18: 67165 | AA18: 18.8 | AB18: 45766 | AG18: 色卡
A19: 17 | B19: 45769 | C19: 陈炎林 | D19: 永叙 | E19: D19-1 | F19: 41112精棉 | H19: SC25006 | I19: 95%棉 5%氨纶 | J19: 95%COTTON 5%SP | K19: 175 | L19: 180 | O19: 染定 | P19: P/D | W19: 欧纺时尚 | X19: 41112 | Y19: 文涛布业 | Z19: 41112精棉 | AA19: 19.6 | AB19: 45766 | AG19: 色卡
A20: 18 | B20: 45769 | C20: 陈炎林 | D20: 永叙 | E20: D19-1 | F20: 3C1005-精棉拉架 | H20: SC25007 | I20: 95%棉 5%氨纶 | J20: 95%COTTON 5%SP | K20: 175 | L20: 180 | O20: 染定 | P20: P/D | W20: 欧纺时尚 | X20: 3C1005 | Y20: 恒信布业 | Z20: 3C1005 | AA20: 15 | AB20: 45766 | AG20: 色卡
A21: 19 | B21: 45769 | C21: 陈炎林 | D21: 永叙 | E21: D19-1 | F21: 3S1203-32支精棉双纱 | H21: SC25008 | I21: 100%棉 | J21: 100%COTTON | K21: 185 | L21: 230 | O21: 染定 | P21: P/D | W21: 欧纺时尚 | X21: 3S1203 | Y21: 恒信布业 | Z21: 3S1203 | AA21: 23.3 | AB21: 45766 | AG21: 色卡
A22: 20 | B22: 45769 | C22: 陈炎林 | D22: 永叙 | E22: D19-1 | F22: 12339#-优棉罗纹 | H22: SC25009 | I22: 95%棉 5%氨纶 | J22: 95%COTTON 5%SP | K22: 145 | L22: 220 | O22: 染定 | P22: P/D | W22: 欧纺时尚 | X22: 12339 | Y22: 锦盛纺织 | Z22: 12339# | AA22: 16.2 | AB22: 45766 | AG22: 色卡
A23: 21 | B23: 45769 | C23: 陈炎林 | D23: 永叙 | E23: D19-1 | F23: 12005#-摩登潮棉 | H23: SC25010 | I23: 100%棉 | J23: 100%COTTON | K23: 185 | L23: 200 | O23: 染定 | P23: P/D | W23: 欧纺时尚 | X23: 12005 | Y23: 锦盛纺织 | Z23: 12005# | AA23: 22 | AB23: 45766 | AG23: 色卡
A24: 22 | B24: 45769 | C24: 陈炎林 | D24: 永叙 | E24: D19-1 | F24: 2031-纯棉满天星网布 | H24: SC25011 | I24: 100%棉 | J24: 100%COTTON | K24: 190 | L24: 130 | O24: 染定 | P24: P/D | W24: 欧纺时尚 | X24: 2031 | Y24: 华联 | Z24: 2031 | AA24: 18 | AB24: 45766 | AG24: 色卡
A25: 23 | B25: 45769 | C25: 陈炎林 | D25: 永叙 | E25: D19-1 | F25: S450 | H25: SC25012 | I25: 100%棉 | J25: 100%COTTON | K25: 145 | O25: 染定 | P25: P/D | W25: 欧纺时尚 | X25: S450 | Y25: 盛业纺织 | Z25: S450 | AA25: 12.7 | AB25: 45766 | AG25: 色卡
A26: 24 | B26: 45773 | C26: 陈炎林 | D26: GFG | F26: 2C1505-21支精棉平纹 | H26: SC25013 | I26: 100%棉 | J26: 100%BCI COTTON | K26: 180 | L26: 180 | O26: 染定 | P26: P/D | W26: 欧纺时尚 | X26: 2C1505 | Y26: 星海 | Z26: 2C1505 | AA26: 17.2 | AB26: 45773 | AG26: 色卡
A27: 25 | B27: 45773 | C27: 陈炎林 | D27: GFG | F27: 3C1505-32支棉平纹拉架 | H27: SC25014 | I27: 95%棉5%氨纶 | J27: 95%BCI COTTON 5%SP | K27: 175 | L27: 180 | O27: 染定 | P27: P/D | W27: 欧纺时尚 | X27: 3C1505 | Y27: 星海 | Z27: 3C1505 | AA27: 13.5 | AB27: 45773 | AG27: 色卡
A28: 26 | B28: 45773 | C28: 陈炎林 | D28: GFG | F28: RM3010-欧丽棉 | H28: SC25015 | I28: 100%棉 | J28: 100%BCI COTTON | K28: 175 | L28: 180 | O28: 染定 | P28: P/D | W28: 欧纺时尚 | X28: RM3010 | Y28: 星海 | Z28: RM3010 | AA28: 13.5 | AB28: 45773 | AG28: 色卡
A29: 27 | B29: 45773 | C29: 陈炎林 | D29: GFG | F29: 2615#-精棉拉架 | H29: SC25016 | I29: 100%棉 | J29: 100%BCI COTTON | K29: 175 | L29: 180 | O29: 染定 | P29: P/D | W29: 欧纺时尚 | X29: 2615# | Y29: 伊彩儿 | Z29: 2615# | AA29: 15.7 | AB29: 45773 | AG29: 色卡
A30: 28 | B30: 45773 | C30: 陈炎林 | D30: GFG | F30: 2619#-纯棉拉架 | H30: SC25017 | I30: 100%棉 | J30: 100%BCI COTTON | K30: 175 | L30: 170 | O30: 染定 | P30: P/D | W30: 欧纺时尚 | X30: 2619# | Y30: 伊彩儿 | Z30: 2619# | AA30: 14.8 | AB30: 45773 | AG30: 色卡
A31: 29 | B31: 45773 | C31: 陈炎林 | D31: GFG | F31: D14454#-32S彩间 | H31: SC25018 | I31: 100%棉 | J31: 100%BCI COTTON | K31: 175 | L31: 180 | O31: 染定 | P31: P/D | W31: 欧纺时尚 | X31: D14454# | Y31: 布布昇 | Z31: D14454# | AA31: 18.1 | AB31: 45773 | AG31: 色卡
A32: 30 | B32: 45773 | C32: 陈炎林 | D32: GFG | F32: 52049#-棉纺系列 | H32: SC25019 | I32: 100%棉 | J32: 100%BCI COTTON | K32: 180 | L32: 190 | O32: 染定 | P32: P/D | W32: 欧纺时尚 | X32: 52049# | Y32: 盛氏布行 | Z32: 52049# | AB32: 45773 | AG32: 色卡
A33: 31 | B33: 45775 | C33: 陈炎林 | D33: GFG | E33: D24-3 | F33: B-0171 | H33: SC25020 | I33: 100%棉 | J33: 100%BCI COTTON | K33: 125 | O33: 染定 | P33: P/D | W33: 欧纺时尚 | X33: B-0171 | Y33: 真成纺织 | Z33: B-0171 | AA33: 15.7 | AB33: 45775 | AG33: 一个循环条
A34: 32 | B34: 45775 | C34: 陈炎林 | D34: GFG | E34: D24-3 | F34: B-029 | H34: SC25020-1 | I34: 100%棉 | J34: 100%BCI COTTON | K34: 125 | O34: 染定 | P34: P/D | W34: 欧纺时尚 | X34: B-029 | Y34: 真成纺织 | Z34: B-029 | AA34: 15.7 | AB34: 45775 | AG34: 一个循环条
A35: 33 | B35: 45775 | C35: 陈炎林 | D35: GFG | E35: D24-3 | F35: A2164 | H35: SC25020-10 | I35: 100%棉 | J35: 100%BCI COTTON | K35: 125 | O35: 染定 | P35: P/D | W35: 欧纺时尚 | X35: A2164 | Y35: 金绣 | Z35: A2164 | AA35: 14.8 | AB35: 45775 | AG35: 一个循环条
A36: 34 | B36: 45775 | C36: 陈炎林 | D36: GFG | E36: D24-3 | F36: A2207 | H36: SC25020-11 | I36: 100%棉 | J36: 100%BCI COTTON | K36: 125 | O36: 染定 | P36: P/D | W36: 欧纺时尚 | X36: A2207 | Y36: 金绣 | Z36: A2207 | AA36: 14.8 | AB36: 45775 | AG36: 一个循环条
A37: 35 | B37: 45775 | C37: 陈炎林 | D37: GFG | E37: D24-3 | F37: A2471 | H37: SC25020-12 | I37: 100%棉 | J37: 100%BCI COTTON | K37: 125 | O37: 染定 | P37: P/D | W37: 欧纺时尚 | X37: A2471 | Y37: 金绣 | Z37: A2471 | AA37: 16.2 | AB37: 45775 | AG37: 一个循环条
A38: 36 | B38: 45775 | C38: 陈炎林 | D38: GFG | E38: D24-3 | F38: A2376 | H38: SC25020-13 | I38: 100%棉 | J38: 100%BCI COTTON | K38: 125 | O38: 染定 | P38: P/D | W38: 欧纺时尚 | X38: A2376 | Y38: 金绣 | Z38: A2376 | AA38: 18.4 | AB38: 45775 | AG38: 一个循环条
A39: 37 | B39: 45775 | C39: 陈炎林 | D39: GFG | E39: D24-3 | F39: A2185 | H39: SC25020-14 | I39: 100%棉 | J39: 100%BCI COTTON | K39: 125 | O39: 染定 | P39: P/D | W39: 欧纺时尚 | X39: A2185 | Y39: 金绣 | Z39: A2185 | AA39: 14.6 | AB39: 45775 | AG39: 一个循环条
A40: 38 | B40: 45775 | C40: 陈炎林 | D40: GFG | E40: D24-3 | F40: F571 | H40: SC25020-15 | I40: 100%棉 | J40: 100%BCI COTTON | K40: 125 | O40: 染定 | P40: P/D | W40: 欧纺时尚 | X40: F571 | Y40: 新发布行 | Z40: F571 | AA40: 14 | AB40: 45775 | AG40: 一个循环条
...

Sheet 正式编号化纤加工别
A1: 信兴隆化纤厂加工别代码一览表 （新表）
A2: 栏位 | B2: 1 | C2: 2 | E2: 3 | G2: 4 | I2: 5 | K2: 6 | M2: 7
A3: 项目 | B3: 染色 | C3: 胶类 | E3: 防水度 | G3: 透湿度 | I3: 泼水度 | K3: 功能 | M3: 压光/特殊加工
A4: 代号 | B4: 说明 | C4: 代号 | D4: 说明 | E4: 代号 | F4: 说明 | G4: 代号 | H4: 说明 | I4: 代号 | J4: 说明 | K4: 代号 | L4: 说明 | M4: 代号 | N4: 说明
A5: O | B5: 无染色 | C5: O | D5: 无上胶 | E5: O | F5: 无水压 | G5: O | H5: 无透湿度 | I5: O | J5: 无泼水 | K5: O | L5: 无功能 | M5: A | N5: PU感温膜 | O5: 新表
A6: A | B6: 磨毛染色 | C6: A | D6: 压克力透明胶 | E6: 1~9 | F6: 100~900mmH2O | G6: 1 | H6: 1000 G/M2.D | I6: S | J6: 一般定型 | K6: F | L6: 阻燃 | M6: B | N6: 双面压光
A7: B | B7: Beam 染色 | C7: B | D7: 水性AC透明胶 | E7: A | F7: 1000mmH2O↑ | G7: 2 | H7: 2000 G/M2.D | I7: T | J7: 柔软定型 | K7: B | L7: UV CUT加工 | M7: C | N7: 压皱
A8: C | B8: 抗氯染色 | C8: C | D8: 压克力白胶 | E8: B | F8: 1500mmH2O↑ | G8: 3 | H8: 3000 G/M2.D | I8: R | J8: C8防水(50-60分） | K8: C | L8: 抗静电 | M8: D | N8: 防绒压光
A9: D | B9: 荧光漂白 | C9: D | D9: 水性AC白胶 | E9: C | F9: 2000mmH2O↑ | G9: 4 | H9: 4000 G/M2.D | I9: C | J9: C8防水3级(70-80分) | K9: D | L9: 抗菌防臭加工 | M9: E | N9: 压花
A10: E | B10: 涤纶本白印花 | C10: E | D10: 水性PU透明胶 | E10: D | F10: 3000mmH2O↑ | G10: 5 | H10: 5000 G/M2.D | I10: N | J10: C8超泼水、三防及含吊牌 | K10: E | L10: 消光 | M10: F | N10: 铁牛印花（滚涂印花）
A11: F | B11: 磨毛抗氯染色 | C11: F | D11: 防火(PU) | E11: E | F11: 5000mmH2O↑ | G11: 6 | H11: 6000 G/M2.D | I11: E | J11: C8防水4级 | K11: G | L11: 吸湿排汗 | M11: K | N11: 正面硅胶,另一面不压光PU涂层
A12: G | B12: 吸湿排汗染色 | C12: I | D12: 离型纸转贴 | E12: F | F12: 10000mmH2O↑ | G12: 7 | H12: 7000 G/M2.D | I12: F | J12: C8三防加工及无吊牌耐洗3-5次 | K12: A | L12: 吸湿排汗易去污 | M12: L | N12: 一般压光
A13: J | B13: JG染色 | C13: J | D13: 珠光胶 | E13: G | F13: 8000mmH2O↑ | G13: 8 | H13: 8000 G/M2.D | I13: B | J13: C8三防无吊牌耐洗10次 | K13: R | L13: 易去污 | M13: O | N13: 不经压光
A14: K | B14: RP染皱染色 | C14: K | D14: UV CUT加工 | E14: H | F14: 20000mmH2O↑ | G14: 9 | H14: 9000 G/M2.D | I14: X | J14: C6防水(50-60分） | K14: Y | L14: 抗黄变定型 | M14: P | N14: PU微多孔膜
A15: R | B15: RP染色 | C15: L | D15: PU色胶 | G15: A | H15: 10000 G/M2.D | I15: J | J15: C6防水3级(70-80分) | K15: H | L15: 防蚊助剂 | M15: S | N15: 压光面做面
A16: Y | B16: 抗黄变染色 | C16: M | D16: 远红外线透湿胶 | G16: B | H16: 15000 G/M2.D | I16: K | J16: C6防水4级 | K16: I | L16: 吸湿速干 | M16: T | N16: 正面硅胶,另一面压光加PU涂层
A17: H | B17: 抗菌染色 | C17: P | D17: PU 印花膜 | G17: C | H17: 20000 G/M2.D | I17: U | J17: C6三防加工及无吊牌耐洗3-5次 | K17: P | L17: 抗花粉整理 | M17: M | N17: 防绒贴条
A18: L | B18: 抗紫外染色 | C18: S | D18: Silicone coating | I18: V | J18: C6三防无吊牌耐洗10次 | K18: S | L18: 树脂 | M18: N | N18: 离型纸转贴作面
A19: P | B19: 染底纸印花 | C19: T | D19: PU透湿白胶 | I19: W | J19: C6超泼水、三防及含吊牌 | K19: J | L19: 胶原蛋白 | M19: W | N19: PU转移远红外线保温印花膜
A20: S | B20: 磨毛+吸湿 | C20: U | D20: PU透明胶 | I20: A | J20: 无氟防水(50-60分） | K20: K | L20: 芳香 | M20: G | N20: 激光冲孔
A21: N | B21: 尼龙印花 | C21: W | D21: PU透明透湿胶 | I21: G | J21: 无氟防水3级(70-80分) | K21: M | L21: 抗菌防霉 | M21: H | N21: 烫金工艺
A22: M | B22: 拉毛+印花 | C22: X | D22: PU白胶 | I22: L | J22: 无氟防水4级 | K22: L | L22: UPF+吸湿排汗 | M22: J | N22: 针织贴合
A23: X | B23: 冷转移印花 | C23: Q | D23: A/C透明强力胶 | I23: P | J23: 无氟防水鲁道夫吊牌 | K23: N | L23: 抗病毒 | M23: I | N23: 海绵复合
A24: Z | B24: 抓绒 | C24: N | D24: PU蜡感胶 | I24: Q | J24: 无氟防水3M吊牌 | K24: P | L24: 凉感 | M24: 2 | N24: 摇粒绒贴合
A25: W | B25: 单上胶 | C25: G | D25: 水性AC色胶 | I25: Y | J25: 无氟防水R3杜邦吊牌 | K25: V | L25: 温控 | M25: 3 | N25: 涂层复合不压光
A26: Q | B26: 重压光染皱 | C26: H | D26: 微多孔湿法透湿白胶 | I26: D | J26: C6三防无吊牌耐洗20次 | M26: 4 | N26: 膜二层复合+压光
C27: V | D27: 微多孔干法透湿白胶 | I27: H | J27: C0三防无吊牌耐洗10次 | M27: 5 | N27: 膜二层复合+不压光
C28: Z | D28: 肤感胶 | M28: 6 | N28: 膜三层复合+压光
C29: 2 | D29: TPU透湿透明膜 | M29: 7 | N29: 膜三层复合+不压光
C30: 3 | D30: TPU透湿白色膜 | M30: 8 | N30: 梭织布贴合
C31: 4 | D31: TPU透湿白色雾面膜 | M31: 9 | N31: 超声波绗棉+无纺布
C32: 5 | D32: TPU透湿雾面膜 | M32: Q | N32: 缝线压花+无纺布
C33: 6 | D33: TPU透湿印花膜 | M33: R | N33: 镭射贴膜
C34: 7 | D34: PU透湿透明膜 | M34: X | N34: EVA复合
C35: 8 | D35: PU透湿白色膜 | M35: Y | N35: PVC复合
C36: 9 | D36: PTFE透湿白色膜 | M36: U | N36: TPU重贴作面
C37: R | D37: 反光材料 | M37: V | N37: 热熔膜
C38: Y | D38: 透明发热胶 | M38: Z | N38: 压花+针织复合
C39: a | D39: 温感色胶 | M39: a | N39: 石墨烯PU高透膜
C40: b | D40: TPU透湿导电印花膜 | M40: b | N40: 夜光膜
...

Sheet 正式编号棉布加工别
A1: 信兴隆棉类产品加工别代码一览表
A2: 栏位 | B2: 1 | C2: 2 | E2: 3 | G2: 4 | I2: 5
A3: 项目 | B3: 染色 | C3: 手感、毛感整理 | E3: 泼水度 | G3: 定型功能 | I3: 胶类
A4: 代号 | B4: 说明 | C4: 代号 | D4: 说明 | E4: 代号 | F4: 说明 | G4: 代号 | H4: 说明 | I4: 代号 | J4: 说明
A5: O | B5: 前处理不染色 | C5: O | D5: 无整理 | E5: O | F5: 无泼水 | G5: O | H5: 无功能 | I5: O | J5: 无上胶
A6: N | B6: 普染/NORMAL FINISHING | C6: M | D6: 磨毛/MICRO SAND | E6: C | F6: 低度泼水(50°-70°)/LOW W/R | G6: F | H6: 阻燃定型/ FLAME RETARDANT | I6: A | J6: 压克力透明胶/A/C COATING
A7: F | B7: 洗褪/FADING AWAY | C7: T | D7: 碳素磨毛/CARBON SUEDE | E7: R | F7: 泼水定型(80°以上)/ W/R | G7: B | H7: 抗紫外线/UV CUT | I7: B | J7: 水性AC透明胶/ WATER BASE A/C COATING
A8: L | B8: 冷染/COLD PAD-BATCH DYEING | C8: R | D8: 抓剪毛/RAISING&SHEARING | E8: T | F8: 柔软定型/ SOFT FINISHING | G8: C | H8: 抗静电加工/ ANTI-STATIC | I8: C | J8: 压克力色胶/A/C COLOR COATING
A9: D | B9: 染底印花/DYEING & PRINTING | C9: H | D9: 磨花/PATTERN SUEDE | E9: U | F9: 泼水柔软定型/ SOFT & W/R FINISHING | G9: D | H9: 抗菌防臭加工/ANTI-MICROBES | I9: E | J9: 水性PU透明胶/ WATER BASE PU COATING
A10: P | B10: 本白印花/PRINTING | C10: S | D10: 仿天丝/SILKY TOUCH | E10: H | F10: 树脂定型/ RESIN FINISHING | G10: S | H10: 三防加工/W/R & O/R & S/R | I10: F | J10: 防火(PU)/FLAME RETARDANT PU COATING
A11: B | B11: 双面印花/BOTH SIDES PRINTING | C11: W | D11: 磨毛+仿天丝/MICRO SAND & SILKY TOUCH | E11: M | F11: 泼水树脂/ RESINATE & W/R | G11: R | H11: 易去污/ S/R | I11: J | J11: 针织拉绒复合
A12: X | B12: 洗褪印花/FADING AWAY & PRINTING | C12: G | D12: 碳磨+仿天丝/MICRO SAND & SILKY TOUCH | E12: N | F12: 超泼水定型/ W/R & O/R | G12: Y | H12: 抗黄变定型/ ANTI-YELLOWING | I12: L | J12: PU色胶(蜡感胶)/ PU COLOR COATING( WAX COATING)
A13: R | B13: 冷染印花/COLD PAD-BATCH DYEING & PRINTING | E13: E | F13: 加强泼水/ ENHANCE W/R | G13: A | H13: 抛松整理（特柔）/AIRO FINISH | I13: S | J13: 硅胶/SIlICONE COATING
A14: Y | B14: 拔印/DISCHARGE PRINTING | I14: T | J14: PU透湿色胶/PU COLOR COATING
A15: H | B15: 烫金/BRONZING | I15: U | J15: PU透明胶/PU COATING
I16: W | J16: PU透明透湿胶/ PU BREATHABLE COATING
I17: Y | J17: 油墨胶/ CARBON COATING
I18: G | J18: 水性AC色胶/ WATER BASE A/C COLOR COATING
I19: H | J19: 水性PU色胶/ WATER BASE PU COLOR COATING
I20: V | J20: 水性PU白胶/ WATER BASE PU MILKY COATING
I21: P | J21: 纸感胶PAPER TOUCHA
I22: I | J22: 亮光胶
I23: K | J23: PU皮感胶
I24: H | J24: 龟裂胶CHAP COATING
I25: Q | J25: TEFLON(10次)
I26: D | J26: 毛感胶
I27: X | J27: 仿记忆胶SHAPE MEMORY COATING
... I30: R | J30: 肤感胶
I31: 2 | J31: 复合二层/2-LAYER LAMINATION
I32: 3 | J32: 复合三层/ 3-LAYER LAMINATION

Sheet 编号规则
A1: 昇奕隆布种命名（布种编号）规则
A2: 更新日期： | B2: 46140
A3: 命名规则：
A4: 1：主要以SY+年份+数字从小到大编号，例如SY26001-SY261001-SY2610001等
A5: 2：鉴于很多产品现货为主，现货色卡有些同底布不同纹路或者加工整理等情况，会出现后缀情况，例如SY26268-3,SY26268-185,SY26269-293-3,其中-3，-185，-293-3是代表其在SY26268/SY26269色卡内的色号或者色卡内的品质代号。
A6: 3：后续有遇到新的问题将持续完善编号规则

Sheet SYL编号表
A1: 昇奕隆编号表 | N1: 胚布信息 | V1: 成品信息
A2: （年/月/日） | B2: *业务员 Owner | C2: 客户 Customer | D2: 布种编号 #Base | E2: 材料名称 Name | F2: 成份（中文) Composition | G2: *成份（英文） Composition | H2: *SPECIFICATION/规格 （经纱支x纬纱支/经密度x纬密度） | I2: 全部加工工艺（中文） Processes | J2: *全部加工工艺（英文） Processes | K2: *可裁门幅 Width | L2: *克重GSM | M2: *厚度mm | N2: *胚布厂 Greige mill | O2: *胚布厂胚布编码 Greige #article | P2: *胚布采购价格RMB/M | V2: *材料成品厂（供应商） FG mill | W2: *成品厂材料编码 FG #article | X2: *成品采购价格RMB/M | Z2: YDGE MOQ/Bulk MOQ 成品码样MOQ/成品大货MOQ | AA2: YDGE L/T/Bulk L/T 成品码样货期/成品大货货期 | AB2: YDGE Surcharge/Bulk Surcharge 成品码样费用/成品大货费用 | AC2: Stock available 成品是否有库存
A3: *开发日期 Creative Date | M3: 塑胶类 | P3: 价格 Price | Q3: 报价日期 Date 年/月/日 | R3: YDGE MOQ/Bulk MOQ 胚布码样MOQ/胚布大货MOQ | S3: YDGE L/T/Bulk L/T 胚布码样货期/胚布大货货期 | T3: YDGE Surcharge/Bulk Surcharge 胚布码样费用/胚布大货费用 | U3: Stock available 胚布是否有库存 | X3: 价格 Price | Y3: 报价日期 Date 年/月/日
A4: 45870 | B4: 陈晓彬 | C4: 中普/茂迪 | D4: SYL25001 / SYL20250927-5 | E4: 灰黑舞龙布 | F4: 100%涤纶 | G4: 100%POLY | H4: 600D*600D | I4: 染泼+PU透明胶 | J4: P/D+W/R+PU COATING | V4: 运邦 | W4: 灰黑舞龙布
A5: 45870 | B5: 陈晓彬 | C5: 乾元 | D5: SYL25002 | E5: 加捻弹力色丁 | F5: 93%尼龙7%氨纶 | G5: 93%NYLON 7%SP | H5: 50D*50D+20D | I5: 染色 | J5: P/D | K5: 145 | L5: 105 | V5: 运邦 | W5: 加捻弹力色丁
A6: 45950 | B6: 陈炎林 | C6: 泰瑞 | D6: SYL25003 | E6: 2/2斜纹 | F6: 100%涤纶 | H6: 150D*16S 0.37MM | I6: P/D | K6: 150 | L6: 204 | V6: 和记 | W6: JP172 1# | Y6: 10.2
A7: 45954 | B7: 陈晓彬 | C7: 中普/茂迪 | D7: SYL25004 | E7: 600D涤纶牛津格子布 | F7: 100%涤纶 | H7: 600D*600D
A8: 45954 | B8: 陈晓彬 | C8: 中普/茂迪 | D8: SYL25005 | E8: 300D涤纶牛津平格 | F8: 100%涤纶 | H8: 300D*300D
A9: 45959 | B9: 陈炎林 | C9: 泰瑞 | D9: SYL25006 | E9: 2/2斜纹 | F9: 100%涤纶 | H9: 150D*10S | I9: P/D | K9: 150 | L9: 242 | V9: 和记 | W9: JP172-1 | Y9: 10.25
A10: 45959 | B10: 陈炎林 | C10: 泰瑞 | D10: SYL25007 | E10: 乐丽丝 | F10: 100%涤纶 | I10: P/D | K10: 145 | L10: 170 | V10: 世贸 | W10: 第二套
A11: 45959 | B11: 陈炎林 | C11: 泰瑞 | D11: SYL25008 | E11: 阳涤 | F11: 100%涤纶 | I11: P/D | K11: 145 | L11: 213 | V11: 世贸 | W11: 第三套
A12: 45961 | B12: 陈炎林 | C12: 泰瑞 | D12: SYL25009 | E12: YCQ3085AU-D | F12: 100%TPU | H12: 0.5±0.02mm | K12: 137 | V12: 福建佳南 | W12: YCQ3085AU-D | Y12: 10.3
A13: 45961 | B13: 陈炎林 | C13: 泰瑞 | D13: SYL25010 | E13: MKN63235 | F13: 100%TPU | H13: 0.5±0.05mm | K13: 132 | V13: 广州明可 | W13: MKN63235 | X13: 28/Y | Y13: 10.31 | Z13: 50/300Y | AA13: 20/30天 | AB13: 150美元/颜色
A14: 45961 | B14: 陈炎林 | C14: 泰瑞 | D14: SYL25011 | E14: MKN63236 | F14: 100%TPU（90A) | H14: 0.5±0.05mm | K14: 132 | V14: 广州明可 | W14: MKN63236 | X14: 32/Y | Y14: 10.31 | Z14: 50/300Y | AA14: 20/30天 | AB14: 150美元/颜色
A15: 45961 | B15: 陈炎林 | C15: 泰瑞 | D15: SYL25012 | E15: 100D双层粗斜四面弹 | F15: 92%POLY8%SP | H15: 100D+40D*100D+40D | I15: P/D | K15: 145 | L15: 280 | V15: 世贸 | W15: FMG251029-4 | X15: 8.5（胚布价） | Y15: 10.31
A16: 45961 | B16: 陈炎林 | C16: 泰瑞 | D16: SYL25013 | E16: TR直贡尼四面弹 | F16: 76%POLY20%Rayon4%SP | H16: 32S+40D*150D+40D | I16: P/D | K16: 145 | L16: 265 | V16: 世贸 | W16: FMG251029-2 | X16: 10（胚布价） | Y16: 10.31
A17: 45961 | B17: 陈炎林 | C17: 泰瑞 | D17: SYL25014 | E17: 300*150复合丝变斜四面弹 | F17: 93%POLY7%SP | H17: 300D+40D*150D+40D | I17: P/D | K17: 145 | L17: 285 | V17: 世贸 | W17: FMG251029-1 | X17: 7.4（胚布价） | Y17: 10.31
A18: 45961 | B18: 陈炎林 | C18: 泰瑞 | D18: SYL25015 | E18: 300D复合丝变斜四面弹 | F18: 93%POLY7%SP | H18: 300D+40D*300D+40D | I18: P/D | K18: 145 | L18: 305 | V18: 世贸 | W18: FMG251029-3 | X18: 7.4（胚布价） | Y18: 10.31
A19: 45966 | B19: 陈炎林 | C19: META | D19: SYL25016 | E19: 75D*75D | F19: 100%涤纶 | H19: 75D*75D | I19: P/D | V19: 卓总提供
A20: 45967 | B20: 陈炎林 | C20: META | D20: SYL25017 | E20: MKN63215 | F20: 60%POLY40%PU | H20: 1.0±0.05mm | I20: P/D | K20: 52" | L20: 600 | V20: 明可 | W20: MKN63215 | X20: 28.5/码（含税含运） | Y20: 45966
A21: 45967 | B21: 陈炎林 | C21: META | D21: SYL25018 | E21: 文字D三层大提花 | F21: 98%POLY2%SP | H21: 100D*150D+300D+150/40D | I21: P/D | K21: 57 | L21: 270 | V21: 世贸 | W21: FMG251024-10 | X21: 11.8（胚布价） | Y21: 45965
A22: 45967 | B22: 陈炎林 | C22: META | D22: SYL25019 | E22: 闪电纹三层大提花 | F22: 98%POLY2%SP | H22: 100D*150D+300D+150/40D | I22: P/D | K22: 57 | L22: 270 | V22: 世贸 | W22: FMG251024-9 | X22: 11.6（胚布价） | Y22: 45965
A23: 45967 | B23: 陈炎林 | C23: META | D23: SYL25020 | E23: 玄武甲三层大提花 | F23: 98%POLY2%SP | H23: 100D*150D+300D+150/40D | I23: P/D | K23: 57 | L23: 276 | V23: 世贸 | W23: FMG251024-8 | X23: 11.8（胚布价） | Y23: 45965
A24: 45967 | B24: 陈炎林 | C24: META | D24: SYL25021 | E24: 龙鳞盾色织大提花 | F24: 100%POLY | H24: 100D*75D | I24: Y/D | K24: 57 | L24: 125 | V24: 世贸 | W24: FMG251024-7 | X24: 14（胚布价） | Y24: 45965
A25: 45967 | B25: 陈炎林 | C25: META | D25: SYL25022 | E25: 万疆大提花 | F25: 100%POLY | H25: 75D*75D | I25: P/D | K25: 57 | L25: 121 | V25: 世贸 | W25: FMG251024-2 | X25: 8（胚布价） | Y25: 45965
A26: 45967 | B26: 陈炎林 | C26: META | D26: SYL25023 | E26: 黑绿色织提花3#丛林 | F26: 100%POLY | H26: 75D*150D | I26: Y/D | K26: 57 | L26: 150 | V26: 世贸 | W26: FMG251024-6 | X26: 13.8（胚布价） | Y26: 45965
A27: 45967 | B27: 陈炎林 | C27: META | D27: SYL25024 | E27: 黑丝色织1#罗纹 | F27: 100%POLY | H27: 75D*150D | I27: Y/D | K27: 57 | L27: 150 | V27: 世贸 | W27: FMG251024-4 | X27: 13.8（胚布价） | Y27: 45965
A28: 45967 | B28: 陈炎林 | C28: META | D28: SYL25025 | E28: 金丝万花色织大提花 | F28: 100%POLY | H28: 150D*150D+300D+金丝 | I28: Y/D | K28: 57 | L28: 187 | V28: 世贸 | W28: FMG251024-3 | X28: 20（胚布价） | Y28: 45965
A29: 45968 | B29: 陈晓彬 | C29: 优步 | D29: SYL25026 | E29: T8酷丝绵登山布 | F29: 100%POLY | H29: 40S*150D+150D | L29: 310 | V29: 运邦-浙江日月梭 | W29: SYL20251105-005
A30: 45968 | B30: 陈晓彬 | C30: 优步 | D30: SYL25027 | E30: 1050D尼龙拷杜拉 | F30: 100%NYLON | H30: 1050D | V30: 运邦 | W30: SYL20251105-001
A31: 45973 | B31: 陈晓彬 | C31: 光瑞 | D31: SYL25028 | E31: 75D加密平桃 | V31: 运邦 | W31: SYL20251110-5
A32: 45975 | B32: 陈炎林 | C32: 泰瑞 | D32: SYL25029 | E32: 2/2斜氨纶加厚 | F32: 98%涤纶2%氨纶 | H32: 150D*600D+70D | V32: 和记 | W32: JP172SP-1 | Y32: 45975
A33: 45978 | B33: 陈晓彬 | C33: 优步 | D33: SYL25030 | E33: 考杜拉四面弹 | F33: 86%尼龙考杜拉 11%氨纶 | H33: (70D+40D)*(70D+40D)+250D/175T*150T | I33: P/D+W/R | K33: 141 | L33: 225 | V33: 运邦 | W33: 考杜拉四面弹
A34: 45985 | B34: 陈炎林 | C34: 泰瑞 | D34: SYL25031 | E34: 双色布 | F34: 100%POLY | H34: 100D*150D+150D+150D+75D | I34: Y/D | K34: 150 | L34: 143 | V34: 和记 | W34: JP182
B35: 陈晓彬 | C35: 光瑞 | D35: SYL25032
A36: 45999 | B36: 陈晓彬 | C36: 兆盈 | D36: SYL25033 | E36: 500D牛津布 | V36: 运邦
A37: 45999 | B37: 陈晓彬 | C37: 兆盈 | D37: SYL25034 | E37: 420D尼龙100T | V37: 运邦
A38: 45999 | B38: 陈晓彬 | C38: 兆盈 | D38: SYL25035 | E38: 尼龙塔丝隆牛津PU明一刀 | V38: 运邦
C39: 兆盈 | D39: SYL25036 | E39: 420D加密 | F39: 100%NYLON | I39: 染泼+PU透明胶 | K39: 58“ | V39: 兆兴 | W39: ZX-3013 | X39: 10.5 | Y39: 46001 | Z39: 100 | AD39: 100码以下，+开剪费1元
C40: 兆盈 | D40: SYL25037 | E40: 500D可提拉 | F40: 100%NYLON | I40: 染泼+PU透明胶 | K40: 58“ | V40: 兆兴 | W40: ZX-5003 | X40: 19 | Y40: 46001 | Z40: 100 | AD40: 100码以下，+开剪费1元
...

Sheet 剪样
A1: 日期 | B1: 加工厂 | C1: 布种编号 | D1: 供应商 | E1: 编号 | F1: 颜色 | G1: 数量 | H1: 单位 | I1: 实际出货数量 | J1: 出货日期 | K1: 销售价 | L1: 销售金额 | M1: 付款方式 | N1: 报价 | O1: 采购价 | P1: 采购金额 | Q1: 备注 | R1: 对账
A2: 45770 | B2: 圣德 | C2: SY25016 | D2: =_xlfn.SINGLE(INDEX(样品编号表!Y:Y,_xlfn.SINGLE(MATCH(_xlfn.SINGLE(C:C),样品编号表!H:H,0)))) -> 光大纺织 | E2: =_xlfn.SINGLE(INDEX(样品编号表!Z:Z,_xlfn.SINGLE(MATCH(_xlfn.SINGLE(C:C),样品编号表!H:H,0)))) -> C580 | F2: 15# | G2: 7 | H2: 米 | I2: 7 | J2: 45771 | K2: 17 | L2: =I2*K2 -> 119 | M2: 微信 | N2: =_xlfn.SINGLE(INDEX(样品编号表!AA:AA,_xlfn.SINGLE(MATCH(_xlfn.SINGLE(C:C),样品编号表!H:H,0)))) -> 9.8 | O2: 14 | P2: =I2*O2 -> 98 | R2: 已对账
A3: 45793 | B3: D&J | C3: SP25032 | D3: =_xlfn.SINGLE(INDEX(样品编号表!Y:Y,_xlfn.SINGLE(MATCH(_xlfn.SINGLE(C:C),样品编号表!H:H,0)))) -> 昌勋纺织 | E3: =_xlfn.SINGLE(INDEX(样品编号表!Z:Z,_xlfn.SINGLE(MATCH(_xlfn.SINGLE(C:C),样品编号表!H:H,0)))) -> C734 | F3: 32# | G3: 4 | H3: 米 | I3: 4 | J3: 45796 | K3: 22 | L3: =I3*K3 -> 88 | M3: 微信 | N3: =_xlfn.SINGLE(INDEX(样品编号表!AA:AA,_xlfn.SINGLE(MATCH(_xlfn.SINGLE(C:C),样品编号表!H:H,0)))) -> 10.8 | O3: 14 | P3: =I3*O3 -> 56 | R3: 已对账
A4: 45801 | B4: 乐力 | C4: AB2364 | D4: 欧纺时尚 | E4: B364 | F4: 白色 | G4: 20 | H4: 米 | I4: 20 | J4: 45803 | K4: 15.6 | L4: =I4*K4 -> 312 | M4: 微信 | N4: 11 | O4: 11 | P4: =I4*O4 -> 220 | R4: 已对账
A5: 45803 | B5: 圣德 | C5: SY25016 | D5: =_xlfn.SINGLE(INDEX(样品编号表!Y:Y,_xlfn.SINGLE(MATCH(_xlfn.SINGLE(C:C),样品编号表!H:H,0)))) -> 光大纺织 | E5: =_xlfn.SINGLE(INDEX(样品编号表!Z:Z,_xlfn.SINGLE(MATCH(_xlfn.SINGLE(C:C),样品编号表!H:H,0)))) -> C580 | F5: 91# | G5: 2 | H5: 米 | I5: 2 | J5: 45804 | K5: 17 | L5: =I5*K5 -> 34 | M5: 微信 | N5: =_xlfn.SINGLE(INDEX(样品编号表!AA:AA,_xlfn.SINGLE(MATCH(_xlfn.SINGLE(C:C),样品编号表!H:H,0)))) -> 9.8 | O5: 14 | P5: =I5*O5 -> 28 | R5: 已对账
A6: 45803 | B6: 圣德 | C6: SY25016 | D6: =_xlfn.SINGLE(INDEX(样品编号表!Y:Y,_xlfn.SINGLE(MATCH(_xlfn.SINGLE(C:C),样品编号表!H:H,0)))) -> 光大纺织 | E6: =_xlfn.SINGLE(INDEX(样品编号表!Z:Z,_xlfn.SINGLE(MATCH(_xlfn.SINGLE(C:C),样品编号表!H:H,0)))) -> C580 | F6: 5# | G6: 1 | H6: 米 | I6: 1 | J6: 45804 | K6: 17 | L6: =I6*K6 -> 17 | M6: 微信 | N6: =_xlfn.SINGLE(INDEX(样品编号表!AA:AA,_xlfn.SINGLE(MATCH(_xlfn.SINGLE(C:C),样品编号表!H:H,0)))) -> 9.8 | O6: 14 | P6: =I6*O6 -> 14 | R6: 已对账
A7: 45814 | B7: 万泰 | C7: SC25020-14 | D7: =_xlfn.SINGLE(INDEX(样品编号表!Y:Y,_xlfn.SINGLE(MATCH(_xlfn.SINGLE(C:C),样品编号表!H:H,0)))) -> 金绣 | E7: =_xlfn.SINGLE(INDEX(样品编号表!Z:Z,_xlfn.SINGLE(MATCH(_xlfn.SINGLE(C:C),样品编号表!H:H,0)))) -> A2185 | F7: 白色 | G7: 6 | H7: 米 | I7: 6 | J7: 45815 | K7: 33 | L7: =I7*K7 -> 198 | M7: 微信 | N7: =_xlfn.SINGLE(INDEX(样品编号表!AA:AA,_xlfn.SINGLE(MATCH(_xlfn.SINGLE(C:C),样品编号表!H:H,0)))) -> 14.6 | O7: 25 | P7: =I7*O7 -> 150 | R7: 已对账
A8: 45814 | B8: 万泰 | C8: SC25020-2 | D8: =_xlfn.SINGLE(INDEX(样品编号表!Y:Y,_xlfn.SINGLE(MATCH(_xlfn.SINGLE(C:C),样品编号表!H:H,0)))) -> 真成纺织 | E8: =_xlfn.SINGLE(INDEX(样品编号表!Z:Z,_xlfn.SINGLE(MATCH(_xlfn.SINGLE(C:C),样品编号表!H:H,0)))) -> B-894 | F8: 白色 | G8: 3 | H8: 米 | I8: 3 | J8: 45815 | K8: 33.7 | L8: =I8*K8 -> 101.1 | M8: 微信 | N8: =_xlfn.SINGLE(INDEX(样品编号表!AA:AA,_xlfn.SINGLE(MATCH(_xlfn.SINGLE(C:C),样品编号表!H:H,0)))) -> 16.5 | O8: 25 | P8: =I8*O8 -> 75 | R8: 已对账
A9: 45817 | B9: 无锡美盛 | C9: SY25063 | D9: =_xlfn.SINGLE(INDEX(样品编号表!Y:Y,_xlfn.SINGLE(MATCH(_xlfn.SINGLE(C:C),样品编号表!H:H,0)))) -> 年年发纺织 | E9: =_xlfn.SINGLE(INDEX(样品编号表!Z:Z,_xlfn.SINGLE(MATCH(_xlfn.SINGLE(C:C),样品编号表!H:H,0)))) -> 303# | F9: 4#米黄色 | G9: 4 | H9: 米 | I9: 4 | J9: 45818 | K9: 21 | L9: =I9*K9 -> 84 | M9: 微信 | N9: =_xlfn.SINGLE(INDEX(样品编号表!AA:AA,_xlfn.SINGLE(MATCH(_xlfn.SINGLE(C:C),样品编号表!H:H,0)))) -> 11.3 | O9: 15 | P9: =I9*O9 -> 60 | R9: 已对账
A10: 45818 | B10: D&J | C10: SY25016 | D10: =_xlfn.SINGLE(INDEX(样品编号表!Y:Y,_xlfn.SINGLE(MATCH(_xlfn.SINGLE(C:C),样品编号表!H:H,0)))) -> 光大纺织 | E10: =_xlfn.SINGLE(INDEX(样品编号表!Z:Z,_xlfn.SINGLE(MATCH(_xlfn.SINGLE(C:C),样品编号表!H:H,0)))) -> C580 | F10: 1#白色 | G10: 6 | H10: 米 | I10: 6 | J10: 45819 | K10: 17 | L10: =I10*K10 -> 102 | M10: 微信 | N10: =_xlfn.SINGLE(INDEX(样品编号表!AA:AA,_xlfn.SINGLE(MATCH(_xlfn.SINGLE(C:C),样品编号表!H:H,0)))) -> 9.8 | O10: 14 | P10: =I10*O10 -> 84 | R10: 已对账
A11: 45828 | B11: 圣德 | C11: SY25016 | D11: =_xlfn.SINGLE(INDEX(样品编号表!Y:Y,_xlfn.SINGLE(MATCH(_xlfn.SINGLE(C:C),样品编号表!H:H,0)))) -> 光大纺织 | E11: =_xlfn.SINGLE(INDEX(样品编号表!Z:Z,_xlfn.SINGLE(MATCH(_xlfn.SINGLE(C:C),样品编号表!H:H,0)))) -> C580 | F11: 91# | G11: 2 | H11: 米 | I11: 2 | J11: 45829 | K11: 17 | L11: =I11*K11 -> 34 | M11: 微信 | N11: =_xlfn.SINGLE(INDEX(样品编号表!AA:AA,_xlfn.SINGLE(MATCH(_xlfn.SINGLE(C:C),样品编号表!H:H,0)))) -> 9.8 | O11: 14 | P11: =I11*O11 -> 28 | R11: 已对账
A12: 45842 | B12: 乐力 | C12: AB2364 | D12: 欧纺时尚 | E12: B364 | F12: 白色 | G12: 20 | H12: 米 | I12: 20 | J12: 45843 | K12: 15.6 | L12: =I12*K12 -> 312 | M12: 微信 | N12: 11 | O12: 11 | P12: =I12*O12 -> 220 | R12: 已对账
A13: 45847 | B13: 万泰 | C13: SC25013 | D13: =_xlfn.SINGLE(INDEX(样品编号表!Y:Y,_xlfn.SINGLE(MATCH(_xlfn.SINGLE(C:C),样品编号表!H:H,0)))) -> 星海 | E13: =_xlfn.SINGLE(INDEX(样品编号表!Z:Z,_xlfn.SINGLE(MATCH(_xlfn.SINGLE(C:C),样品编号表!H:H,0)))) -> 2C1505 | F13: 4#咖色 | G13: 2 | H13: 米 | I13: 2 | J13: 45850 | K13: 30 | L13: =I13*K13 -> 60 | M13: 微信 | N13: =_xlfn.SINGLE(INDEX(样品编号表!AA:AA,_xlfn.SINGLE(MATCH(_xlfn.SINGLE(C:C),样品编号表!H:H,0)))) -> 17.2 | O13: 30 | P13: =I13*O13 -> 60 | R13: 已对账
A14: 45847 | B14: 万泰 | C14: SC25013 | D14: =_xlfn.SINGLE(INDEX(样品编号表!Y:Y,_xlfn.SINGLE(MATCH(_xlfn.SINGLE(C:C),样品编号表!H:H,0)))) -> 星海 | E14: =_xlfn.SINGLE(INDEX(样品编号表!Z:Z,_xlfn.SINGLE(MATCH(_xlfn.SINGLE(C:C),样品编号表!H:H,0)))) -> 2C1505 | F14: 6#黑白 | G14: 2 | H14: 米 | I14: 2 | J14: 45850 | K14: 30 | L14: =I14*K14 -> 60 | M14: 微信 | N14: =_xlfn.SINGLE(INDEX(样品编号表!AA:AA,_xlfn.SINGLE(MATCH(_xlfn.SINGLE(C:C),样品编号表!H:H,0)))) -> 17.2 | O14: 30 | P14: =I14*O14 -> 60 | R14: 已对账
A15: 45854 | B15: 扑喜 | C15: SY25567 | D15: =_xlfn.SINGLE(INDEX(样品编号表!Y:Y,_xlfn.SINGLE(MATCH(_xlfn.SINGLE(C:C),样品编号表!H:H,0)))) -> 恒鑫 | E15: =_xlfn.SINGLE(INDEX(样品编号表!Z:Z,_xlfn.SINGLE(MATCH(_xlfn.SINGLE(C:C),样品编号表!H:H,0)))) -> 1090A# | F15: 1#白色 | G15: 1 | H15: 米 | I15: 1 | J15: 45855 | K15: 26 | L15: =I15*K15 -> 26 | M15: 微信 | N15: =_xlfn.SINGLE(INDEX(样品编号表!AA:AA,_xlfn.SINGLE(MATCH(_xlfn.SINGLE(C:C),样品编号表!H:H,0)))) -> 13.5 | O15: 20 | P15: =I15*O15 -> 20 | R15: 已对账
A16: 45863 | B16: 圣德 | C16: SY25016 | D16: =_xlfn.SINGLE(INDEX(样品编号表!Y:Y,_xlfn.SINGLE(MATCH(_xlfn.SINGLE(C:C),样品编号表!H:H,0)))) -> 光大纺织 | E16: =_xlfn.SINGLE(INDEX(样品编号表!Z:Z,_xlfn.SINGLE(MATCH(_xlfn.SINGLE(C:C),样品编号表!H:H,0)))) -> C580 | F16: 5# | G16: 1 | H16: 米 | I16: 1 | J16: 45866 | K16: 17 | L16: =I16*K16 -> 17 | M16: 微信 | N16: =_xlfn.SINGLE(INDEX(样品编号表!AA:AA,_xlfn.SINGLE(MATCH(_xlfn.SINGLE(C:C),样品编号表!H:H,0)))) -> 9.8 | O16: 14 | P16: =I16*O16 -> 14 | R16: 已对账
A17: 45869 | B17: 倍德 | C17: SP25051 | D17: =_xlfn.SINGLE(INDEX(样品编号表!Y:Y,_xlfn.SINGLE(MATCH(_xlfn.SINGLE(C:C),样品编号表!H:H,0)))) -> 马利布行 | E17: =_xlfn.SINGLE(INDEX(样品编号表!Z:Z,_xlfn.SINGLE(MATCH(_xlfn.SINGLE(C:C),样品编号表!H:H,0)))) -> 10172# | F17: 1#黑色 | G17: 3 | H17: 米 | I17: 3 | J17: 45871 | K17: 25.7 | L17: =I17*K17 -> 77.1 | M17: 微信 | N17: =_xlfn.SINGLE(INDEX(样品编号表!AA:AA,_xlfn.SINGLE(MATCH(_xlfn.SINGLE(C:C),样品编号表!H:H,0)))) -> 12.2 | O17: 17 | P17: =I17*O17 -> 51 | R17: 已对账
A18: 45874 | B18: 万泰 | C18: SY25827 | D18: =_xlfn.SINGLE(INDEX(样品编号表!Y:Y,_xlfn.SINGLE(MATCH(_xlfn.SINGLE(C:C),样品编号表!H:H,0)))) -> 万利行 | E18: =_xlfn.SINGLE(INDEX(样品编号表!Z:Z,_xlfn.SINGLE(MATCH(_xlfn.SINGLE(C:C),样品编号表!H:H,0)))) -> 521-2# | F18: 64#土黄色 | G18: 7 | H18: 米 | I18: 7 | J18: 45880 | K18: 21.1 | L18: =I18*K18 -> 147.7 | M18: 微信 | N18: =_xlfn.SINGLE(INDEX(样品编号表!AA:AA,_xlfn.SINGLE(MATCH(_xlfn.SINGLE(C:C),样品编号表!H:H,0)))) -> 10.5 | O18: 16 | P18: =I18*O18 -> 112 | R18: 已对账
A19: 45874 | B19: 万泰 | C19: SY25827 | D19: =_xlfn.SINGLE(INDEX(样品编号表!Y:Y,_xlfn.SINGLE(MATCH(_xlfn.SINGLE(C:C),样品编号表!H:H,0)))) -> 万利行 | E19: =_xlfn.SINGLE(INDEX(样品编号表!Z:Z,_xlfn.SINGLE(MATCH(_xlfn.SINGLE(C:C),样品编号表!H:H,0)))) -> 521-2# | F19: 3#米白色 | G19: 23 | H19: 米 | I19: 23 | J19: 45880 | K19: 21.1 | L19: =I19*K19 -> 485.3 | M19: 微信 | N19: =_xlfn.SINGLE(INDEX(样品编号表!AA:AA,_xlfn.SINGLE(MATCH(_xlfn.SINGLE(C:C),样品编号表!H:H,0)))) -> 10.5 | O19: 11 | P19: =I19*O19 -> 253 | R19: 已对账
A20: 45875 | B20: 杰登 | C20: SY25531 | D20: =_xlfn.SINGLE(INDEX(样品编号表!Y:Y,_xlfn.SINGLE(MATCH(_xlfn.SINGLE(C:C),样品编号表!H:H,0)))) -> 凯盛亨 | E20: =_xlfn.SINGLE(INDEX(样品编号表!Z:Z,_xlfn.SINGLE(MATCH(_xlfn.SINGLE(C:C),样品编号表!H:H,0)))) -> 839# | F20: 1#白色 | G20: 3 | H20: 米 | I20: 3 | J20: 45879 | K20: 20 | L20: =I20*K20 -> 60 | M20: 支付宝 | N20: =_xlfn.SINGLE(INDEX(样品编号表!AA:AA,_xlfn.SINGLE(MATCH(_xlfn.SINGLE(C:C),样品编号表!H:H,0)))) -> 11.3 | O20: 16 | P20: =I20*O20 -> 48 | R20: 已对账
A21: 45876 | B21: D&J | C21: SY25016 | D21: =_xlfn.SINGLE(INDEX(样品编号表!Y:Y,_xlfn.SINGLE(MATCH(_xlfn.SINGLE(C:C),样品编号表!H:H,0)))) -> 光大纺织 | E21: =_xlfn.SINGLE(INDEX(样品编号表!Z:Z,_xlfn.SINGLE(MATCH(_xlfn.SINGLE(C:C),样品编号表!H:H,0)))) -> C580 | F21: 1#白色 | G21: 2 | H21: 米 | I21: 2 | J21: 45877 | K21: 17 | L21: =I21*K21 -> 34 | M21: 微信 | N21: =_xlfn.SINGLE(INDEX(样品编号表!AA:AA,_xlfn.SINGLE(MATCH(_xlfn.SINGLE(C:C),样品编号表!H:H,0)))) -> 9.8 | O21: 14 | P21: =I21*O21 -> 28 | R21: 已对账
A22: 45876 | B22: D&J | C22: SY25287 | D22: =_xlfn.SINGLE(INDEX(样品编号表!Y:Y,_xlfn.SINGLE(MATCH(_xlfn.SINGLE(C:C),样品编号表!H:H,0)))) -> 宝隆纺织 | E22: =_xlfn.SINGLE(INDEX(样品编号表!Z:Z,_xlfn.SINGLE(MATCH(_xlfn.SINGLE(C:C),样品编号表!H:H,0)))) -> 1562 | F22: 51#淡蓝色 | G22: 3 | H22: 米 | I22: 3 | J22: 45877 | K22: 21 | L22: =I22*K22 -> 63 | M22: 微信 | N22: =_xlfn.SINGLE(INDEX(样品编号表!AA:AA,_xlfn.SINGLE(MATCH(_xlfn.SINGLE(C:C),样品编号表!H:H,0)))) -> 6.8 | O22: 12 | P22: =I22*O22 -> 36 | R22: 已对账
A23: 45876 | B23: D&J | C23: SY25287 | D23: =_xlfn.SINGLE(INDEX(样品编号表!Y:Y,_xlfn.SINGLE(MATCH(_xlfn.SINGLE(C:C),样品编号表!H:H,0)))) -> 宝隆纺织 | E23: =_xlfn.SINGLE(INDEX(样品编号表!Z:Z,_xlfn.SINGLE(MATCH(_xlfn.SINGLE(C:C),样品编号表!H:H,0)))) -> 1562 | F23: 53#棕色 | G23: 2 | H23: 米 | I23: 2 | J23: 45881 | K23: 21 | L23: =I23*K23 -> 42 | M23: 微信 | N23: =_xlfn.SINGLE(INDEX(样品编号表!AA:AA,_xlfn.SINGLE(MATCH(_xlfn.SINGLE(C:C),样品编号表!H:H,0)))) -> 6.8 | O23: 12 | P23: =I23*O23 -> 24 | R23: 已对账
A24: 45876 | B24: 圣德 | C24: SY25531 | D24: =_xlfn.SINGLE(INDEX(样品编号表!Y:Y,_xlfn.SINGLE(MATCH(_xlfn.SINGLE(C:C),样品编号表!H:H,0)))) -> 凯盛亨 | E24: =_xlfn.SINGLE(INDEX(样品编号表!Z:Z,_xlfn.SINGLE(MATCH(_xlfn.SINGLE(C:C),样品编号表!H:H,0)))) -> 839# | F24: 43#黄油色 | G24: 2 | H24: 米 | I24: 2 | J24: 45879 | K24: 20 | L24: =I24*K24 -> 40 | M24: 微信 | N24: =_xlfn.SINGLE(INDEX(样品编号表!AA:AA,_xlfn.SINGLE(MATCH(_xlfn.SINGLE(C:C),样品编号表!H:H,0)))) -> 11.3 | O24: 16 | P24: =I24*O24 -> 32 | R24: 已对账
... A40: 45919 | B40: D&J | C40: SY25544 | D40: =_xlfn.SINGLE(INDEX(样品编号表!Y:Y,_xlfn.SINGLE(MATCH(_xlfn.SINGLE(C:C),样品编号表!H:H,0)))) -> 润森 | E40: =_xlfn.SINGLE(INDEX(样品编号表!Z:Z,_xlfn.SINGLE(MATCH(_xlfn.SINGLE(C:C),样品编号表!H:H,0)))) -> 华尔缎 | F40: 98#深绿色 | G40: 8 | H40: 米 | I40: 7 | J40: 45925 | K40: 18 | L40: =I40*K40 -> 126 | M40: 微信 | N40: =_xlfn.SINGLE(INDEX(样品编号表!AA:AA,_xlfn.SINGLE(MATCH(_xlfn.SINGLE(C:C),样品编号表!H:H,0)))) -> 10.5 | O40: 15 | P40: =I40*O40 -> 105 | R40: 已对账
A41: 45919 | B41: D&J | C41: SY25544 | D41: =_xlfn.SINGLE(INDEX(样品编号表!Y:Y,_xlfn.SINGLE(MATCH(_xlfn.SINGLE(C:C),样品编号表!H:H,0)))) -> 润森 | E41: =_xlfn.SINGLE(INDEX(样品编号表!Z:Z,_xlfn.SINGLE(MATCH(_xlfn.SINGLE(C:C),样品编号表!H:H,0)))) -> 华尔缎 | F41: 120#米白 | G41: 3 | H41: 米 | I41: 2 | J41: 45925 | K41: 18 | L41: =I41*K41 -> 36 | M41: 微信 | N41: =_xlfn.SINGLE(INDEX(样品编号表!AA:AA,_xlfn.SINGLE(MATCH(_xlfn.SINGLE(C:C),样品编号表!H:H,0)))) -> 10.5 | O41: 15 | P41: =I41*O41 -> 30 | Q41: 已对账 | R41: 已对账
A42: 45923 | B42: BTC | C42: SP25051 | D42: =_xlfn.SINGLE(INDEX(样品编号表!Y:Y,_xlfn.SINGLE(MATCH(_xlfn.SINGLE(C:C),样品编号表!H:H,0)))) -> 马利布行 | E42: =_xlfn.SINGLE(INDEX(样品编号表!Z:Z,_xlfn.SINGLE(MATCH(_xlfn.SINGLE(C:C),样品编号表!H:H,0)))) -> 10172# | F42: 16#酒红色 | G42: 2 | H42: 米 | I42: 2 | J42: 45926 | K42: 25.7 | L42: =I42*K42 -> 51.4 | M42: 微信 | N42: =_xlfn.SINGLE(INDEX(样品编号表!AA:AA,_xlfn.SINGLE(MATCH(_xlfn.SINGLE(C:C),样品编号表!H:H,0)))) -> 12.2 | O42: 17 | P42: =I42*O42 -> 34 | R42: 已对账
A43: 45923 | B43: BTC | C43: SY25776 | D43: =_xlfn.SINGLE(INDEX(样品编号表!Y:Y,_xlfn.SINGLE(MATCH(_xlfn.SINGLE(C:C),样品编号表!H:H,0)))) -> 新合盛布业 | E43: =_xlfn.SINGLE(INDEX(样品编号表!Z:Z,_xlfn.SINGLE(MATCH(_xlfn.SINGLE(C:C),样品编号表!H:H,0)))) -> 8112 | F43: 米白色 | G43: 14 | H43: 米 | I43: 14 | J43: 45926 | K43: 17 | L43: =I43*K43 -> 238 | M43: 微信 | N43: =_xlfn.SINGLE(INDEX(样品编号表!AA:AA,_xlfn.SINGLE(MATCH(_xlfn.SINGLE(C:C),样品编号表!H:H,0)))) -> 9.6 | O43: 14 | P43: =I43*O43 -> 196 | R43: 已对账
A44: 45923 | B44: BTC | C44: SY25776 | D44: =_xlfn.SINGLE(INDEX(样品编号表!Y:Y,_xlfn.SINGLE(MATCH(_xlfn.SINGLE(C:C),样品编号表!H:H,0)))) -> 新合盛布业 | E44: =_xlfn.SINGLE(INDEX(样品编号表!Z:Z,_xlfn.SINGLE(MATCH(_xlfn.SINGLE(C:C),样品编号表!H:H,0)))) -> 8112 | F44: 2#黑色 | G44: 3 | H44: 米 | I44: 3 | J44: 45926 | K44: 17 | L44: =I44*K44 -> 51 | M44: 微信 | N44: =_xlfn.SINGLE(INDEX(样品编号表!AA:AA,_xlfn.SINGLE(MATCH(_xlfn.SINGLE(C:C),样品编号表!H:H,0)))) -> 9.6 | O44: 14 | P44: =I44*O44 -> 42 | Q44: 已对账 | R44: 已对账
A45: 45925 | B45: 三佰 | C45: SY25419 | D45: =_xlfn.SINGLE(INDEX(样品编号表!Y:Y,_xlfn.SINGLE(MATCH(_xlfn.SINGLE(C:C),样品编号表!H:H,0)))) -> 艺纺 | E45: =_xlfn.SINGLE(INDEX(样品编号表!Z:Z,_xlfn.SINGLE(MATCH(_xlfn.SINGLE(C:C),样品编号表!H:H,0)))) -> 11865-3 | F45: 9#棕色 | G45: 3 | H45: 米 | I45: 3 | J45: 45929 | K45: 25 | L45: =I45*K45 -> 75 | M45: 微信 | N45: =_xlfn.SINGLE(INDEX(样品编号表!AA:AA,_xlfn.SINGLE(MATCH(_xlfn.SINGLE(C:C),样品编号表!H:H,0)))) -> 12.8 | O45: 18 | P45: =I45*O45 -> 54 | R45: 已对账
A46: 45926 | B46: BTC | C46: SY25738 | D46: =_xlfn.SINGLE(INDEX(样品编号表!Y:Y,_xlfn.SINGLE(MATCH(_xlfn.SINGLE(C:C),样品编号表!H:H,0)))) -> 新嘉彩 | E46: =_xlfn.SINGLE(INDEX(样品编号表!Z:Z,_xlfn.SINGLE(MATCH(_xlfn.SINGLE(C:C),样品编号表!H:H,0)))) -> 938 | F46: 2#黑色 | G46: 3 | H46: 米 | I46: 3 | J46: 45926 | K46: 20 | L46: =I46*K46 -> 60 | M46: 微信 | N46: =_xlfn.SINGLE(INDEX(样品编号表!AA:AA,_xlfn.SINGLE(MATCH(_xlfn.SINGLE(C:C),样品编号表!H:H,0)))) -> 8.8 | O46: 15 | P46: =I46*O46 -> 45 | Q46: 已对账 | R46: 已对账
A47: 45926 | B47: BTC | C47: SY25776 | D47: =_xlfn.SINGLE(INDEX(样品编号表!Y:Y,_xlfn.SINGLE(MATCH(_xlfn.SINGLE(C:C),样品编号表!H:H,0)))) -> 新合盛布业 | E47: =_xlfn.SINGLE(INDEX(样品编号表!Z:Z,_xlfn.SINGLE(MATCH(_xlfn.SINGLE(C:C),样品编号表!H:H,0)))) -> 8112 | F47: 2#黑色 | G47: 4 | H47: 米 | I47: 4 | J47: 45926 | K47: 17 | L47: =I47*K47 -> 68 | M47: 微信 | N47: =_xlfn.SINGLE(INDEX(样品编号表!AA:AA,_xlfn.SINGLE(MATCH(_xlfn.SINGLE(C:C),样品编号表!H:H,0)))) -> 9.6 | O47: 14 | P47: =I47*O47 -> 56 | Q47: 已对账 | R47: 已对账
A48: 45930 | B48: D&J | C48: SY25722 | D48: =_xlfn.SINGLE(INDEX(样品编号表!Y:Y,_xlfn.SINGLE(MATCH(_xlfn.SINGLE(C:C),样品编号表!H:H,0)))) -> 锦地印染 | E48: =_xlfn.SINGLE(INDEX(样品编号表!Z:Z,_xlfn.SINGLE(MATCH(_xlfn.SINGLE(C:C),样品编号表!H:H,0)))) -> 10993 | F48: 米白色 | G48: 2 | H48: 米 | I48: 2 | J48: 45937 | K48: 20 | L48: =I48*K48 -> 40 | M48: 微信 | N48: =_xlfn.SINGLE(INDEX(样品编号表!AA:AA,_xlfn.SINGLE(MATCH(_xlfn.SINGLE(C:C),样品编号表!H:H,0)))) -> 8.2 | O48: 14 | P48: =I48*O48 -> 28 | Q48: 已对账 | R48: 已对账
A49: 45930 | B49: 三佰 | C49: SY25722 | D49: =_xlfn.SINGLE(INDEX(样品编号表!Y:Y,_xlfn.SINGLE(MATCH(_xlfn.SINGLE(C:C),样品编号表!H:H,0)))) -> 锦地印染 | E49: =_xlfn.SINGLE(INDEX(样品编号表!Z:Z,_xlfn.SINGLE(MATCH(_xlfn.SINGLE(C:C),样品编号表!H:H,0)))) -> 10993 | F49: 30#黑色 | G49: 1 | H49: 米 | I49: 1 | J49: 45937 | K49: 20 | L49: =I49*K49 -> 20 | M49: 微信 | N49: =_xlfn.SINGLE(INDEX(样品编号表!AA:AA,_xlfn.SINGLE(MATCH(_xlfn.SINGLE(C:C),样品编号表!H:H,0)))) -> 8.2 | O49: 14 | P49: =I49*O49 -> 14 | Q49: 已对账 | R49: 已对账
A50: 45930 | B50: 三佰 | C50: SY25738 | D50: =_xlfn.SINGLE(INDEX(样品编号表!Y:Y,_xlfn.SINGLE(MATCH(_xlfn.SINGLE(C:C),样品编号表!H:H,0)))) -> 新嘉彩 | E50: =_xlfn.SINGLE(INDEX(样品编号表!Z:Z,_xlfn.SINGLE(MATCH(_xlfn.SINGLE(C:C),样品编号表!H:H,0)))) -> 938 | F50: 76# | G50: 3 | H50: 米 | I50: 3 | J50: 45937 | K50: 22 | L50: =I50*K50 -> 66 | M50: 微信 | N50: =_xlfn.SINGLE(INDEX(样品编号表!AA:AA,_xlfn.SINGLE(MATCH(_xlfn.SINGLE(C:C),样品编号表!H:H,0)))) -> 8.8 | O50: 15 | P50: =I50*O50 -> 45 | Q50: 已对账 | R50: 已对账
A51: 45930 | B51: 三佰 | C51: SY25738 | D51: =_xlfn.SINGLE(INDEX(样品编号表!Y:Y,_xlfn.SINGLE(MATCH(_xlfn.SINGLE(C:C),样品编号表!H:H,0)))) -> 新嘉彩 | E51: =_xlfn.SINGLE(INDEX(样品编号表!Z:Z,_xlfn.SINGLE(MATCH(_xlfn.SINGLE(C:C),样品编号表!H:H,0)))) -> 938 | F51: 118# | G51: 3 | H51: 米 | I51: 3 | J51: 45937 | K51: 22 | L51: =I51*K51 -> 66 | M51: 微信 | N51: =_xlfn.SINGLE(INDEX(样品编号表!AA:AA,_xlfn.SINGLE(MATCH(_xlfn.SINGLE(C:C),样品编号表!H:H,0)))) -> 8.8 | O51: 15 | P51: =I51*O51 -> 45 | Q51: 已对账 | R51: 已对账
A52: 45930 | B52: 三佰 | C52: SY25776 | D52: =_xlfn.SINGLE(INDEX(样品编号表!Y:Y,_xlfn.SINGLE(MATCH(_xlfn.SINGLE(C:C),样品编号表!H:H,0)))) -> 新合盛布业 | E52: =_xlfn.SINGLE(INDEX(样品编号表!Z:Z,_xlfn.SINGLE(MATCH(_xlfn.SINGLE(C:C),样品编号表!H:H,0)))) -> 8112 | F52: 2#黑色 | G52: 2 | H52: 米 | I52: 2 | J52: 45937 | K52: 21 | L52: =I52*K52 -> 42 | M52: 微信 | N52: =_xlfn.SINGLE(INDEX(样品编号表!AA:AA,_xlfn.SINGLE(MATCH(_xlfn.SINGLE(C:C),样品编号表!H:H,0)))) -> 9.6 | O52: 14 | P52: =I52*O52 -> 28 | Q52: 已对账 | R52: 已对账
A53: 45933 | B53: 杰登 | C53: SY25544 | D53: =_xlfn.SINGLE(INDEX(样品编号表!Y:Y,_xlfn.SINGLE(MATCH(_xlfn.SINGLE(C:C),样品编号表!H:H,0)))) -> 润森 | E53: =_xlfn.SINGLE(INDEX(样品编号表!Z:Z,_xlfn.SINGLE(MATCH(_xlfn.SINGLE(C:C),样品编号表!H:H,0)))) -> 华尔缎 | F53: 1#白色 | G53: 2 | H53: 米 | I53: 2 | J53: 45937 | K53: 18 | L53: =I53*K53 -> 36 | M53: 支付宝 | N53: =_xlfn.SINGLE(INDEX(样品编号表!AA:AA,_xlfn.SINGLE(MATCH(_xlfn.SINGLE(C:C),样品编号表!H:H,0)))) -> 10.5 | O53: 15 | P53: =I53*O53 -> 30 | Q53: 已对账 | R53: 已对账
A54: 45939 | B54: BTC | C54: SY25776 | D54: =_xlfn.SINGLE(INDEX(样品编号表!Y:Y,_xlfn.SINGLE(MATCH(_xlfn.SINGLE(C:C),样品编号表!H:H,0)))) -> 新合盛布业 | E54: =_xlfn.SINGLE(INDEX(样品编号表!Z:Z,_xlfn.SINGLE(MATCH(_xlfn.SINGLE(C:C),样品编号表!H:H,0)))) -> 8112 | F54: 本白 | G54: 9 | H54: 米 | I54: 9 | J54: 45940 | K54: 17 | L54: =I54*K54 -> 153 | M54: 微信 | N54: =_xlfn.SINGLE(INDEX(样品编号表!AA:AA,_xlfn.SINGLE(MATCH(_xlfn.SINGLE(C:C),样品编号表!H:H,0)))) -> 9.6 | O54: 14 | P54: =I54*O54 -> 126 | R54: 已对账
A55: 45939 | B55: 万泰 | C55: SY25824 | D55: =_xlfn.SINGLE(INDEX(样品编号表!Y:Y,_xlfn.SINGLE(MATCH(_xlfn.SINGLE(C:C),样品编号表!H:H,0)))) -> 合泰隆纺织 | E55: =_xlfn.SINGLE(INDEX(样品编号表!Z:Z,_xlfn.SINGLE(MATCH(_xlfn.SINGLE(C:C),样品编号表!H:H,0)))) -> T985 | F55: 21#藏青&白色 | G55: 6 | H55: 米 | I55: 6 | J55: 45940 | K55: 24 | L55: =I55*K55 -> 144 | M55: 微信 | N55: =_xlfn.SINGLE(INDEX(样品编号表!AA:AA,_xlfn.SINGLE(MATCH(_xlfn.SINGLE(C:C),样品编号表!H:H,0)))) -> 10.8 | O55: 18 | P55: =I55*O55 -> 108 | Q55: 布小帮 | R55: 已对账
...

Sheet 大货
A1: 日期 | B1: 加工厂 | C1: 订单号 | D1: 款号 | E1: 布种编号 | F1: 供应商 | G1: 编号 | H1: 颜色 | I1: 数量 | J1: 单位 | K1: 实际出货数量 | L1: 出货日期 | M1: 销售价 | N1: 销售金额 | O1: 付款方式 | P1: 是否需要证书 | Q1: 证书类型 | R1: 最迟开证时间 | S1: 实际开证时间 | T1: 采购价 | U1: 采购金额 | V1: 备注
A2: 45863 | B2: 乐力 | C2: XXL2507001 | E2: AB2364 | F2: 欧纺时尚 | G2: B364 | H2: 白色 | I2: 1700 | J2: 米 | K2: 1635 | L2: 45882 | M2: 15.6 | N2: =K2*M2 -> 25506 | O2: 现金+TC | T2: 8.1 | U2: =K2*T2 -> 13243.5 | V2: 待出证书
A3: 45869 | B3: 无锡美盛 | C3: XXL2507002 | E3: SY25063 | F3: =_xlfn.SINGLE(INDEX(样品编号表!Y:Y,_xlfn.SINGLE(MATCH(_xlfn.SINGLE(E:E),样品编号表!H:H,0)))) -> 年年发纺织 | G3: =_xlfn.SINGLE(INDEX(样品编号表!Z:Z,_xlfn.SINGLE(MATCH(_xlfn.SINGLE(E:E),样品编号表!H:H,0)))) -> 303# | H3: 35#绿色 | I3: 270 | J3: 米 | K3: 287 | L3: 45874 | M3: 15.3 | N3: =K3*M3 -> 4391.1 | O3: 现金转账 | T3: 11.3 | U3: =K3*T3 -> 3243.1
A4: 45887 | B4: 乐力 | C4: XXL2507001 | E4: AB2364 | F4: 欧纺时尚 | G4: B364 | H4: 白色 | I4: 310 | J4: 米 | K4: 351 | L4: 45889 | M4: 15.6 | N4: =K4*M4 -> 5475.6 | O4: 现金+TC | T4: 8.1 | U4: =K4*T4 -> 2843.1 | V4: 待出证书
A5: 45892 | B5: 圣德 | C5: SYL-SD2508001 | E5: SY25531 | F5: =_xlfn.SINGLE(INDEX(样品编号表!Y:Y,_xlfn.SINGLE(MATCH(_xlfn.SINGLE(E:E),样品编号表!H:H,0)))) -> 凯盛亨 | G5: =_xlfn.SINGLE(INDEX(样品编号表!Z:Z,_xlfn.SINGLE(MATCH(_xlfn.SINGLE(E:E),样品编号表!H:H,0)))) -> 839# | H5: 43#黄油色 | I5: 544 | J5: 米 | K5: 589 | L5: 45892 | M5: 14.7 | N5: =K5*M5 -> 8658.3 | O5: 现金转账 | T5: 11.3 | U5: =K5*T5 -> 6655.7
A6: 45898 | B6: 圣德 | E6: SY25531 | F6: =_xlfn.SINGLE(INDEX(样品编号表!Y:Y,_xlfn.SINGLE(MATCH(_xlfn.SINGLE(E:E),样品编号表!H:H,0)))) -> 凯盛亨 | G6: =_xlfn.SINGLE(INDEX(样品编号表!Z:Z,_xlfn.SINGLE(MATCH(_xlfn.SINGLE(E:E),样品编号表!H:H,0)))) -> 839# | H6: 43#黄油色 | I6: 205 | J6: 米 | K6: 227 | L6: 45912 | M6: 14.7 | N6: =K6*M6 -> 3336.9 | O6: 现金转账 | T6: 11.3 | U6: =K6*T6 -> 2565.1
A7: 45898 | B7: 韦欣 | E7: SY25016 | F7: =_xlfn.SINGLE(INDEX(样品编号表!Y:Y,_xlfn.SINGLE(MATCH(_xlfn.SINGLE(E:E),样品编号表!H:H,0)))) -> 光大纺织 | G7: =_xlfn.SINGLE(INDEX(样品编号表!Z:Z,_xlfn.SINGLE(MATCH(_xlfn.SINGLE(E:E),样品编号表!H:H,0)))) -> C580 | H7: 2#白色 | I7: 190 | J7: 米 | K7: 217 | L7: 45912 | M7: 14.4 | N7: =K7*M7 -> 3124.8 | O7: 发票+BCI | T7: 9.8 | U7: =K7*T7 -> 2126.6 | V7: 开票+BCI证书
A8: 45898 | B8: 韦欣 | E8: SY25016 | F8: =_xlfn.SINGLE(INDEX(样品编号表!Y:Y,_xlfn.SINGLE(MATCH(_xlfn.SINGLE(E:E),样品编号表!H:H,0)))) -> 光大纺织 | G8: =_xlfn.SINGLE(INDEX(样品编号表!Z:Z,_xlfn.SINGLE(MATCH(_xlfn.SINGLE(E:E),样品编号表!H:H,0)))) -> C580 | H8: 40#粉色 | I8: 190 | J8: 米 | K8: 215 | L8: 45912 | M8: 14.4 | N8: =K8*M8 -> 3096 | O8: 发票+BCI | T8: 9.8 | U8: =K8*T8 -> 2107 | V8: 开票+BCI证书
A9: 45918 | B9: 圣德 | E9: SY25531 | F9: =_xlfn.SINGLE(INDEX(样品编号表!Y:Y,_xlfn.SINGLE(MATCH(_xlfn.SINGLE(E:E),样品编号表!H:H,0)))) -> 凯盛亨 | G9: =_xlfn.SINGLE(INDEX(样品编号表!Z:Z,_xlfn.SINGLE(MATCH(_xlfn.SINGLE(E:E),样品编号表!H:H,0)))) -> 839# | H9: 白底咖兰花 | I9: 122 | J9: 米 | K9: 118 | L9: 45945 | M9: 27.1 | N9: =K9*M9 -> 3197.8 | O9: 现金 | T9: =9+10.9 -> 19.9 | U9: =K9*T9 -> 2348.2
A10: 45919 | B10: 韦恩 | E10: SY25016 | F10: =_xlfn.SINGLE(INDEX(样品编号表!Y:Y,_xlfn.SINGLE(MATCH(_xlfn.SINGLE(E:E),样品编号表!H:H,0)))) -> 光大纺织 | G10: =_xlfn.SINGLE(INDEX(样品编号表!Z:Z,_xlfn.SINGLE(MATCH(_xlfn.SINGLE(E:E),样品编号表!H:H,0)))) -> C580 | H10: 154#黑色 | I10: 300 | J10: 米 | K10: 306 | L10: 45922 | M10: 14.4 | N10: =K10*M10 -> 4406.4 | O10: 发票+BCI | T10: 9.8 | U10: =K10*T10 -> 2998.8 | V10: 退109米，补发90米，19*14.4=273.6元待后续订单抵扣，开票+BCI证书
A11: 45919 | B11: 杰登 | E11: SY25531 | F11: =_xlfn.SINGLE(INDEX(样品编号表!Y:Y,_xlfn.SINGLE(MATCH(_xlfn.SINGLE(E:E),样品编号表!H:H,0)))) -> 凯盛亨 | G11: =_xlfn.SINGLE(INDEX(样品编号表!Z:Z,_xlfn.SINGLE(MATCH(_xlfn.SINGLE(E:E),样品编号表!H:H,0)))) -> 839# | H11: 白底咖兰花 | I11: 290 | J11: 米 | K11: 288 | L11: 45945 | M11: 27.1 | N11: =K11*M11 -> 7804.8 | O11: 现金 | T11: =9+10.9 -> 19.9 | U11: =K11*T11 -> 5731.2
A12: 45919 | B12: 杰登 | E12: SY25531 | F12: =_xlfn.SINGLE(INDEX(样品编号表!Y:Y,_xlfn.SINGLE(MATCH(_xlfn.SINGLE(E:E),样品编号表!H:H,0)))) -> 凯盛亨 | G12: =_xlfn.SINGLE(INDEX(样品编号表!Z:Z,_xlfn.SINGLE(MATCH(_xlfn.SINGLE(E:E),样品编号表!H:H,0)))) -> 839# | H12: 白底咖兰花 | I12: 260 | J12: 米 | K12: 260 | L12: 45945 | M12: 27.1 | N12: =K12*M12 -> 7046 | O12: 现金 | T12: =9+10.9 -> 19.9 | U12: =K12*T12 -> 5174
A13: 45919 | B13: 杰登 | E13: SY25531 | F13: =_xlfn.SINGLE(INDEX(样品编号表!Y:Y,_xlfn.SINGLE(MATCH(_xlfn.SINGLE(E:E),样品编号表!H:H,0)))) -> 凯盛亨 | G13: =_xlfn.SINGLE(INDEX(样品编号表!Z:Z,_xlfn.SINGLE(MATCH(_xlfn.SINGLE(E:E),样品编号表!H:H,0)))) -> 839# | H13: 黑色 | I13: 260 | J13: 米 | K13: 265 | L13: 45947 | M13: 14.7 | N13: =K13*M13 -> 3895.5 | O13: 现金 | T13: 11.3 | U13: =K13*T13 -> 2994.5
A14: 45947 | B14: 杰登 | E14: SY25531 | F14: =_xlfn.SINGLE(INDEX(样品编号表!Y:Y,_xlfn.SINGLE(MATCH(_xlfn.SINGLE(E:E),样品编号表!H:H,0)))) -> 凯盛亨 | G14: =_xlfn.SINGLE(INDEX(样品编号表!Z:Z,_xlfn.SINGLE(MATCH(_xlfn.SINGLE(E:E),样品编号表!H:H,0)))) -> 839# | H14: 白底咖兰花 | I14: 65 | J14: 米 | K14: 65 | L14: 45951 | M14: 27.1 | N14: =K14*M14 -> 1761.5 | O14: 现金 | T14: =9+10.9 -> 19.9 | U14: =K14*T14 -> 1293.5
A15: 45947 | B15: 万泰 | E15: SY25824 | F15: =_xlfn.SINGLE(INDEX(样品编号表!Y:Y,_xlfn.SINGLE(MATCH(_xlfn.SINGLE(E:E),样品编号表!H:H,0)))) -> 合泰隆纺织 | G15: =_xlfn.SINGLE(INDEX(样品编号表!Z:Z,_xlfn.SINGLE(MATCH(_xlfn.SINGLE(E:E),样品编号表!H:H,0)))) -> T985 | H15: 5#浅绿色&白色 | I15: 210 | J15: 米 | K15: 218.5 | L15: 45947 | M15: 15.1 | N15: =K15*M15 -> 3299.35 | O15: 发票 | T15: 10.8 | U15: =K15*T15 -> 2359.8 | V15: 待开票 布小帮
A16: 45948 | B16: 万泰 | E16: SY25824 | F16: =_xlfn.SINGLE(INDEX(样品编号表!Y:Y,_xlfn.SINGLE(MATCH(_xlfn.SINGLE(E:E),样品编号表!H:H,0)))) -> 合泰隆纺织 | G16: =_xlfn.SINGLE(INDEX(样品编号表!Z:Z,_xlfn.SINGLE(MATCH(_xlfn.SINGLE(E:E),样品编号表!H:H,0)))) -> T985 | H16: #21藏青&白色 | I16: 305 | J16: 米 | K16: 319 | L16: 45950 | M16: 15.1 | N16: =K16*M16 -> 4816.9 | O16: 发票 | T16: 10.8 | U16: =K16*T16 -> 3445.2 | V16: 待开票 布小帮
A17: 45950 | B17: BTC | E17: SY25738 | F17: =_xlfn.SINGLE(INDEX(样品编号表!Y:Y,_xlfn.SINGLE(MATCH(_xlfn.SINGLE(E:E),样品编号表!H:H,0)))) -> 新嘉彩 | G17: =_xlfn.SINGLE(INDEX(样品编号表!Z:Z,_xlfn.SINGLE(MATCH(_xlfn.SINGLE(E:E),样品编号表!H:H,0)))) -> 938 | H17: 2#黑色 | I17: 690 | J17: 米 | K17: 691 | L17: 45952 | M17: 14.4 | N17: =K17*M17 -> 9950.4 | O17: 发票+TC | T17: 10.3 | U17: =K17*T17 -> 7117.3
A18: 45950 | B18: BTC | E18: SY25738 | F18: =_xlfn.SINGLE(INDEX(样品编号表!Y:Y,_xlfn.SINGLE(MATCH(_xlfn.SINGLE(E:E),样品编号表!H:H,0)))) -> 新嘉彩 | G18: =_xlfn.SINGLE(INDEX(样品编号表!Z:Z,_xlfn.SINGLE(MATCH(_xlfn.SINGLE(E:E),样品编号表!H:H,0)))) -> 938 | H18: 32#黄色 | I18: 90 | J18: 米 | K18: 112 | L18: 45952 | M18: 14.4 | N18: =K18*M18 -> 1612.8 | O18: 发票+TC | T18: 10.3 | U18: =K18*T18 -> 1153.6
A19: 45950 | B19: BTC | E19: SY25738 | F19: =_xlfn.SINGLE(INDEX(样品编号表!Y:Y,_xlfn.SINGLE(MATCH(_xlfn.SINGLE(E:E),样品编号表!H:H,0)))) -> 新嘉彩 | G19: =_xlfn.SINGLE(INDEX(样品编号表!Z:Z,_xlfn.SINGLE(MATCH(_xlfn.SINGLE(E:E),样品编号表!H:H,0)))) -> 938 | H19: 77#蓝色 | I19: 90 | J19: 米 | K19: 108 | L19: 45952 | M19: 14.4 | N19: =K19*M19 -> 1555.2 | O19: 发票+TC | T19: 10.3 | U19: =K19*T19 -> 1112.4
A20: 45950 | B20: BTC | E20: SP25051 | F20: =_xlfn.SINGLE(INDEX(样品编号表!Y:Y,_xlfn.SINGLE(MATCH(_xlfn.SINGLE(E:E),样品编号表!H:H,0)))) -> 马利布行 | G20: =_xlfn.SINGLE(INDEX(样品编号表!Z:Z,_xlfn.SINGLE(MATCH(_xlfn.SINGLE(E:E),样品编号表!H:H,0)))) -> 10172# | H20: 黑色 | I20: 60 | J20: 米 | K20: 67 | L20: 45958 | M20: 18.7 | N20: =K20*M20 -> 1252.9 | O20: 发票+TC | T20: 12.2 | U20: =K20*T20 -> 817.4 | V20: 开票+证书
A21: 45952 | B21: 圣德 | E21: SY25531 | F21: =_xlfn.SINGLE(INDEX(样品编号表!Y:Y,_xlfn.SINGLE(MATCH(_xlfn.SINGLE(E:E),样品编号表!H:H,0)))) -> 凯盛亨 | G21: =_xlfn.SINGLE(INDEX(样品编号表!Z:Z,_xlfn.SINGLE(MATCH(_xlfn.SINGLE(E:E),样品编号表!H:H,0)))) -> 839# | H21: 9#淡紫色 | I21: 382 | J21: 米 | K21: 378 | L21: 45966 | M21: 14.7 | N21: =K21*M21 -> 5556.6 | O21: 现金 | U21: =K21*T21 -> 0 | V21: 不需要开票/证书
A22: 45955 | B22: 杰登 | D22: TUS0358-A | E22: SY25544 | F22: =_xlfn.SINGLE(INDEX(样品编号表!Y:Y,_xlfn.SINGLE(MATCH(_xlfn.SINGLE(E:E),样品编号表!H:H,0)))) -> 润森 | G22: =_xlfn.SINGLE(INDEX(样品编号表!Z:Z,_xlfn.SINGLE(MATCH(_xlfn.SINGLE(E:E),样品编号表!H:H,0)))) -> 华尔缎 | H22: 108#黑色 | I22: 265 | J22: 米 | K22: 265 | L22: 45963 | M22: 16.1 | N22: =K22*M22 -> 4266.5 | O22: 开票+TC
A23: 45955 | B23: 杰登 | D23: TUS0287-A | E23: SY25544 | F23: =_xlfn.SINGLE(INDEX(样品编号表!Y:Y,_xlfn.SINGLE(MATCH(_xlfn.SINGLE(E:E),样品编号表!H:H,0)))) -> 润森 | G23: =_xlfn.SINGLE(INDEX(样品编号表!Z:Z,_xlfn.SINGLE(MATCH(_xlfn.SINGLE(E:E),样品编号表!H:H,0)))) -> 华尔缎 | H23: 108#黑色 | I23: 200 | J23: 米 | K23: 200 | L23: 45963 | M23: 16.1 | N23: =K23*M23 -> 3220 | O23: 开票+TC
A24: 45958 | B24: 杰登 | D24: TUS0303-A | E24: SY25544 | F24: =_xlfn.SINGLE(INDEX(样品编号表!Y:Y,_xlfn.SINGLE(MATCH(_xlfn.SINGLE(E:E),样品编号表!H:H,0)))) -> 润森 | G24: =_xlfn.SINGLE(INDEX(样品编号表!Z:Z,_xlfn.SINGLE(MATCH(_xlfn.SINGLE(E:E),样品编号表!H:H,0)))) -> 华尔缎 | H24: 108#黑色 | I24: 185 | J24: 米 | K24: 185 | L24: 45963 | M24: 16.1 | N24: =K24*M24 -> 2978.5 | O24: 开票+TC
A25: 45958 | B25: 杰登 | D25: TUS0316-A | E25: SY25544 | F25: =_xlfn.SINGLE(INDEX(样品编号表!Y:Y,_xlfn.SINGLE(MATCH(_xlfn.SINGLE(E:E),样品编号表!H:H,0)))) -> 润森 | G25: =_xlfn.SINGLE(INDEX(样品编号表!Z:Z,_xlfn.SINGLE(MATCH(_xlfn.SINGLE(E:E),样品编号表!H:H,0)))) -> 华尔缎 | H25: 108#黑色 | I25: 305 | J25: 米 | K25: 328 | L25: 45963 | M25: 16.1 | N25: =K25*M25 -> 5280.8 | O25: 开票+TC
A26: 45955 | B26: 杰登 | D26: TUS0358-B | E26: SY25544 | F26: =_xlfn.SINGLE(INDEX(样品编号表!Y:Y,_xlfn.SINGLE(MATCH(_xlfn.SINGLE(E:E),样品编号表!H:H,0)))) -> 润森 | G26: =_xlfn.SINGLE(INDEX(样品编号表!Z:Z,_xlfn.SINGLE(MATCH(_xlfn.SINGLE(E:E),样品编号表!H:H,0)))) -> 华尔缎 | H26: 117#浅兰色 | I26: 265 | J26: 米 | K26: 273 | L26: 45963 | M26: 16.1 | N26: =K26*M26 -> 4395.3 | O26: 开票+TC
A27: 45958 | B27: 杰登 | D27: TUS0480-A | E27: SY25544 | F27: =_xlfn.SINGLE(INDEX(样品编号表!Y:Y,_xlfn.SINGLE(MATCH(_xlfn.SINGLE(E:E),样品编号表!H:H,0)))) -> 润森 | G27: =_xlfn.SINGLE(INDEX(样品编号表!Z:Z,_xlfn.SINGLE(MATCH(_xlfn.SINGLE(E:E),样品编号表!H:H,0)))) -> 华尔缎 | H27: 117#浅兰色 | I27: 90 | J27: 米 | K27: 90 | L27: 45963 | M27: 16.1 | N27: =K27*M27 -> 1449 | O27: 开票+TC
A28: 45955 | B28: 杰登 | D28: TUS0287-B | E28: SY25544 | F28: =_xlfn.SINGLE(INDEX(样品编号表!Y:Y,_xlfn.SINGLE(MATCH(_xlfn.SINGLE(E:E),样品编号表!H:H,0)))) -> 润森 | G28: =_xlfn.SINGLE(INDEX(样品编号表!Z:Z,_xlfn.SINGLE(MATCH(_xlfn.SINGLE(E:E),样品编号表!H:H,0)))) -> 华尔缎 | H28: 1#白色 | I28: 200 | J28: 米 | K28: 221 | L28: 45963 | M28: 16.1 | N28: =K28*M28 -> 3558.1 | O28: 开票+TC
A29: 45958 | B29: 杰登 | D29: TUS0316-B | E29: SY25544 | F29: =_xlfn.SINGLE(INDEX(样品编号表!Y:Y,_xlfn.SINGLE(MATCH(_xlfn.SINGLE(E:E),样品编号表!H:H,0)))) -> 润森 | G29: =_xlfn.SINGLE(INDEX(样品编号表!Z:Z,_xlfn.SINGLE(MATCH(_xlfn.SINGLE(E:E),样品编号表!H:H,0)))) -> 华尔缎 | H29: 91#米黄色 | I29: 200 | J29: 米 | K29: 236 | L29: 45963 | M29: 16.1 | N29: =K29*M29 -> 3799.6 | O29: 开票+TC
A30: 45958 | B30: 杰登 | D30: TUS0315-A | E30: SY25544 | F30: =_xlfn.SINGLE(INDEX(样品编号表!Y:Y,_xlfn.SINGLE(MATCH(_xlfn.SINGLE(E:E),样品编号表!H:H,0)))) -> 润森 | G30: =_xlfn.SINGLE(INDEX(样品编号表!Z:Z,_xlfn.SINGLE(MATCH(_xlfn.SINGLE(E:E),样品编号表!H:H,0)))) -> 华尔缎 | H30: 85#墨绿色 | I30: 255 | J30: 米 | K30: 267 | L30: 45965 | M30: 16.1 | N30: =K30*M30 -> 4298.7 | O30: 开票+TC
A31: 45958 | B31: 杰登 | D31: TUS0480-B | E31: SY25544 | F31: =_xlfn.SINGLE(INDEX(样品编号表!Y:Y,_xlfn.SINGLE(MATCH(_xlfn.SINGLE(E:E),样品编号表!H:H,0)))) -> 润森 | G31: =_xlfn.SINGLE(INDEX(样品编号表!Z:Z,_xlfn.SINGLE(MATCH(_xlfn.SINGLE(E:E),样品编号表!H:H,0)))) -> 华尔缎 | H31: 85#墨绿色 | I31: 90 | J31: 米 | K31: 90 | L31: 45965 | M31: 16.1 | N31: =K31*M31 -> 1449 | O31: 开票+TC
A32: 45966 | B32: 杰登 | E32: SY25544 | F32: =_xlfn.SINGLE(INDEX(样品编号表!Y:Y,_xlfn.SINGLE(MATCH(_xlfn.SINGLE(E:E),样品编号表!H:H,0)))) -> 润森 | G32: =_xlfn.SINGLE(INDEX(样品编号表!Z:Z,_xlfn.SINGLE(MATCH(_xlfn.SINGLE(E:E),样品编号表!H:H,0)))) -> 华尔缎 | H32: 117#浅兰色 | I32: 40 | J32: 米 | K32: 40 | L32: 45968 | M32: 16.1 | N32: =K32*M32 -> 644 | O32: 开票+TC
A33: 45969 | B33: 杰登 | D33: TUS0322-A/1390 | E33: SY25544 | F33: =_xlfn.SINGLE(INDEX(样品编号表!Y:Y,_xlfn.SINGLE(MATCH(_xlfn.SINGLE(E:E),样品编号表!H:H,0)))) -> 润森 | G33: =_xlfn.SINGLE(INDEX(样品编号表!Z:Z,_xlfn.SINGLE(MATCH(_xlfn.SINGLE(E:E),样品编号表!H:H,0)))) -> 华尔缎 | H33: 108#黑色 | I33: 235 | J33: 米 | K33: 253 | L33: 45979 | M33: 16.1 | N33: =K33*M33 -> 4073.3 | O33: 开票+TC | T33: 10.3 | U33: =K33*T33 -> 2605.9
A34: 45971 | B34: 圣德 | C34: WACA001297 | D34: CAL0223-A | E34: SP25028 | F34: =_xlfn.SINGLE(INDEX(样品编号表!Y:Y,_xlfn.SINGLE(MATCH(_xlfn.SINGLE(E:E),样品编号表!H:H,0)))) -> 新合盛布业 | G34: =_xlfn.SINGLE(INDEX(样品编号表!Z:Z,_xlfn.SINGLE(MATCH(_xlfn.SINGLE(E:E),样品编号表!H:H,0)))) -> 6002 | H34: 黑色 | I34: 331 | J34: 米 | K34: 339 | L34: 45978 | M34: 10.3 | N34: =K34*M34 -> 3491.7 | O34: 开票+TC | T34: 6.6 | U34: =K34*T34 -> 2237.4
A35: 45971 | B35: BTC | E35: SP25051 | F35: =_xlfn.SINGLE(INDEX(样品编号表!Y:Y,_xlfn.SINGLE(MATCH(_xlfn.SINGLE(E:E),样品编号表!H:H,0)))) -> 马利布行 | G35: =_xlfn.SINGLE(INDEX(样品编号表!Z:Z,_xlfn.SINGLE(MATCH(_xlfn.SINGLE(E:E),样品编号表!H:H,0)))) -> 10172# | H35: 16#酒红色 | I35: 38 | J35: 米 | K35: 38 | L35: 45985 | M35: 18.7 | N35: =K35*M35 -> 710.6 | O35: 发票+TC | V35: 开票+证书
A36: 45971 | B36: BTC | E36: SY25738 | F36: =_xlfn.SINGLE(INDEX(样品编号表!Y:Y,_xlfn.SINGLE(MATCH(_xlfn.SINGLE(E:E),样品编号表!H:H,0)))) -> 新嘉彩 | G36: =_xlfn.SINGLE(INDEX(样品编号表!Z:Z,_xlfn.SINGLE(MATCH(_xlfn.SINGLE(E:E),样品编号表!H:H,0)))) -> 938 | H36: 63#白色 | I36: 106 | J36: 米 | K36: 106 | L36: 45985 | M36: 14.5 | N36: =K36*M36 -> 1537 | O36: 发票+TC | T36: 10.3 | U36: =K36*T36 -> 1091.8 | V36: 开票+证书
A37: 45971 | B37: BTC | E37: SY25738 | F37: =_xlfn.SINGLE(INDEX(样品编号表!Y:Y,_xlfn.SINGLE(MATCH(_xlfn.SINGLE(E:E),样品编号表!H:H,0)))) -> 新嘉彩 | G37: =_xlfn.SINGLE(INDEX(样品编号表!Z:Z,_xlfn.SINGLE(MATCH(_xlfn.SINGLE(E:E),样品编号表!H:H,0)))) -> 938 | H37: 63#白色 | I37: 341 | J37: 米 | K37: 366 | L37: 45985 | M37: 14.5 | N37: =K37*M37 -> 5307 | O37: 发票+TC | T37: 10.3 | U37: =K37*T37 -> 3769.8 | V37: 开票+证书
A38: 45974 | B38: BTC | E38: SY251062 | F38: =_xlfn.SINGLE(INDEX(样品编号表!Y:Y,_xlfn.SINGLE(MATCH(_xlfn.SINGLE(E:E),样品编号表!H:H,0)))) -> 万顺纺织 | G38: =_xlfn.SINGLE(INDEX(样品编号表!Z:Z,_xlfn.SINGLE(MATCH(_xlfn.SINGLE(E:E),样品编号表!H:H,0)))) -> A8784 | H38: 50#黑色 | I38: 1646 | J38: 米 | K38: 1653 | L38: 45985 | M38: 13.4 | N38: =K38*M38 -> 22150.2 | O38: 发票+TC | V38: 开票+证书
A39: 45974 | B39: BTC | E39: SY251062 | F39: =_xlfn.SINGLE(INDEX(样品编号表!Y:Y,_xlfn.SINGLE(MATCH(_xlfn.SINGLE(E:E),样品编号表!H:H,0)))) -> 万顺纺织 | G39: =_xlfn.SINGLE(INDEX(样品编号表!Z:Z,_xlfn.SINGLE(MATCH(_xlfn.SINGLE(E:E),样品编号表!H:H,0)))) -> A8784 | H39: 58#巧克力色 | I39: 1441 | J39: 米 | K39: 1433 | L39: 45985 | M39: 13.4 | N39: =K39*M39 -> 19202.2 | O39: 发票+TC | V39: 开票+证书
A40: 45974 | B40: BTC | E40: SY251062 | F40: =_xlfn.SINGLE(INDEX(样品编号表!Y:Y,_xlfn.SINGLE(MATCH(_xlfn.SINGLE(E:E),样品编号表!H:H,0)))) -> 万顺纺织 | G40: =_xlfn.SINGLE(INDEX(样品编号表!Z:Z,_xlfn.SINGLE(MATCH(_xlfn.SINGLE(E:E),样品编号表!H:H,0)))) -> A8784 | H40: 4#柠檬黄 | I40: 828 | J40: 米 | K40: 818 | L40: 45985 | M40: 13.9 | N40: =K40*M40 -> 11370.2 | O40: 发票+TC | V40: 开票+证书
...

Sheet 留底
A1: 日期 | B1: 加工厂 | C1: 订单类型 | D1: 布种编号 | E1: 供应商 | F1: 编号 | G1: 颜色 | H1: 数量 | I1: 单位 | J1: 采购价 | K1: 金额 | L1: 备注
A2: 45775 | B2: XXL | C2: 留底 | D2: SY25016 | E2: =_xlfn.SINGLE(INDEX(样品编号表!Y:Y,_xlfn.SINGLE(MATCH(_xlfn.SINGLE(D:D),样品编号表!H:H,0)))) -> 光大纺织 | F2: =_xlfn.SINGLE(INDEX(样品编号表!Z:Z,_xlfn.SINGLE(MATCH(_xlfn.SINGLE(D:D),样品编号表!H:H,0)))) -> C580 | G2: 15# | H2: 1 | I2: 米 | J2: 14 | K2: =H2*J2 -> 14
A3: 45793 | B3: XXL | C3: 留底 | D3: SP25032 | E3: =_xlfn.SINGLE(INDEX(样品编号表!Y:Y,_xlfn.SINGLE(MATCH(_xlfn.SINGLE(D:D),样品编号表!H:H,0)))) -> 昌勋纺织 | F3: =_xlfn.SINGLE(INDEX(样品编号表!Z:Z,_xlfn.SINGLE(MATCH(_xlfn.SINGLE(D:D),样品编号表!H:H,0)))) -> C734 | G3: 32# | H3: 1 | I3: 米 | J3: 14 | K3: =H3*J3 -> 14
A4: 45814 | B4: XXL | C4: 留底 | D4: SC25020-14 | E4: =_xlfn.SINGLE(INDEX(样品编号表!Y:Y,_xlfn.SINGLE(MATCH(_xlfn.SINGLE(D:D),样品编号表!H:H,0)))) -> 金绣 | F4: =_xlfn.SINGLE(INDEX(样品编号表!Z:Z,_xlfn.SINGLE(MATCH(_xlfn.SINGLE(D:D),样品编号表!H:H,0)))) -> A2185 | G4: 白色 | H4: 1 | I4: 米 | J4: 33 | K4: 25
A5: 45814 | B5: XXL | C5: 留底 | D5: SC25020-2 | E5: =_xlfn.SINGLE(INDEX(样品编号表!Y:Y,_xlfn.SINGLE(MATCH(_xlfn.SINGLE(D:D),样品编号表!H:H,0)))) -> 真成纺织 | F5: =_xlfn.SINGLE(INDEX(样品编号表!Z:Z,_xlfn.SINGLE(MATCH(_xlfn.SINGLE(D:D),样品编号表!H:H,0)))) -> B-894 | G5: 白色 | H5: 1 | I5: 米 | J5: 33.7 | K5: 25
A6: 45817 | B6: XXL | C6: 留底 | D6: SY25063 | E6: =_xlfn.SINGLE(INDEX(样品编号表!Y:Y,_xlfn.SINGLE(MATCH(_xlfn.SINGLE(D:D),样品编号表!H:H,0)))) -> 年年发纺织 | F6: =_xlfn.SINGLE(INDEX(样品编号表!Z:Z,_xlfn.SINGLE(MATCH(_xlfn.SINGLE(D:D),样品编号表!H:H,0)))) -> 303# | G6: 4#米黄色 | H6: 1 | I6: 米 | J6: 21 | K6: 16
A7: 45776 | B7: XXL | C7: 留底 | D7: SP25035 | E7: =_xlfn.SINGLE(INDEX(样品编号表!Y:Y,_xlfn.SINGLE(MATCH(_xlfn.SINGLE(D:D),样品编号表!H:H,0)))) -> 华联 | F7: =_xlfn.SINGLE(INDEX(样品编号表!Z:Z,_xlfn.SINGLE(MATCH(_xlfn.SINGLE(D:D),样品编号表!H:H,0)))) -> 3926-10# | G7: 70# | H7: 2 | I7: 米 | J7: 18 | K7: =H7*J7 -> 36
A8: 45776 | B8: XXL | C8: 留底 | E8: 华强纺织 | F8: 8265-1 | G8: 37# | H8: 1 | I8: 米 | J8: 14 | K8: =H8*J8 -> 14
A9: 45776 | B9: XXL | C9: 留底 | E9: 华强纺织 | F9: 8265-1 | G9: 38# | H9: 1 | I9: 米 | J9: 14 | K9: =H9*J9 -> 14
A10: 45791 | B10: XXL | C10: 留底 | D10: SY25066 | E10: =_xlfn.SINGLE(INDEX(样品编号表!Y:Y,_xlfn.SINGLE(MATCH(_xlfn.SINGLE(D:D),样品编号表!H:H,0)))) -> 展业布行 | F10: =_xlfn.SINGLE(INDEX(样品编号表!Z:Z,_xlfn.SINGLE(MATCH(_xlfn.SINGLE(D:D),样品编号表!H:H,0)))) -> ZY138# | G10: 59# | H10: 1 | I10: 米 | J10: 30 | K10: =H10*J10 -> 30
A11: 45791 | B11: XXL | C11: 留底 | D11: SY25069 | E11: =_xlfn.SINGLE(INDEX(样品编号表!Y:Y,_xlfn.SINGLE(MATCH(_xlfn.SINGLE(D:D),样品编号表!H:H,0)))) -> 东盛恒旺布行 | F11: =_xlfn.SINGLE(INDEX(样品编号表!Z:Z,_xlfn.SINGLE(MATCH(_xlfn.SINGLE(D:D),样品编号表!H:H,0)))) -> 39008# | G11: 137# | H11: 1 | I11: 米 | J11: 30 | K11: =H11*J11 -> 30
A12: 45799 | B12: XXL | C12: 留底 | D12: SC25022 | E12: =_xlfn.SINGLE(INDEX(样品编号表!Y:Y,_xlfn.SINGLE(MATCH(_xlfn.SINGLE(D:D),样品编号表!H:H,0)))) -> 欧纺时尚 | F12: =_xlfn.SINGLE(INDEX(样品编号表!Z:Z,_xlfn.SINGLE(MATCH(_xlfn.SINGLE(D:D),样品编号表!H:H,0)))) -> 686#（金丝棉） | G12: 白色 | H12: 1 | I12: 米 | J12: 10 | K12: =H12*J12 -> 10
A13: 45799 | B13: XXL | C13: 留底 | D13: SP25040 | E13: =_xlfn.SINGLE(INDEX(样品编号表!Y:Y,_xlfn.SINGLE(MATCH(_xlfn.SINGLE(D:D),样品编号表!H:H,0)))) -> 欧纺时尚 | F13: =_xlfn.SINGLE(INDEX(样品编号表!Z:Z,_xlfn.SINGLE(MATCH(_xlfn.SINGLE(D:D),样品编号表!H:H,0)))) -> 75D全光 | G13: 白色 | H13: 1 | I13: 米 | J13: 12 | K13: =H13*J13 -> 12
A14: 45799 | B14: XXL | C14: 留底 | D14: SP25039 | E14: =_xlfn.SINGLE(INDEX(样品编号表!Y:Y,_xlfn.SINGLE(MATCH(_xlfn.SINGLE(D:D),样品编号表!H:H,0)))) -> 欧纺时尚 | F14: =_xlfn.SINGLE(INDEX(样品编号表!Z:Z,_xlfn.SINGLE(MATCH(_xlfn.SINGLE(D:D),样品编号表!H:H,0)))) -> 50D全光加厚 | G14: 白色 | H14: 1 | I14: 米 | J14: 12 | K14: =H14*J14 -> 12
A15: 45799 | B15: XXL | C15: 留底 | D15: SP25041 | E15: =_xlfn.SINGLE(INDEX(样品编号表!Y:Y,_xlfn.SINGLE(MATCH(_xlfn.SINGLE(D:D),样品编号表!H:H,0)))) -> 精品里布 | F15: =_xlfn.SINGLE(INDEX(样品编号表!Z:Z,_xlfn.SINGLE(MATCH(_xlfn.SINGLE(D:D),样品编号表!H:H,0)))) -> 加舒美绸 | G15: 白色 | H15: 1 | I15: 米 | J15: 6 | K15: =H15*J15 -> 6
A16: 45799 | B16: XXL | C16: 留底 | D16: SP25042 | E16: =_xlfn.SINGLE(INDEX(样品编号表!Y:Y,_xlfn.SINGLE(MATCH(_xlfn.SINGLE(D:D),样品编号表!H:H,0)))) -> 精品里布 | F16: =_xlfn.SINGLE(INDEX(样品编号表!Z:Z,_xlfn.SINGLE(MATCH(_xlfn.SINGLE(D:D),样品编号表!H:H,0)))) -> 精品韩国里 （加韩）80克 | G16: 白色 | H16: 1 | I16: 米 | J16: 5 | K16: =H16*J16 -> 5
A17: 45799 | B17: XXL | C17: 留底 | D17: SP25044 | E17: =_xlfn.SINGLE(INDEX(样品编号表!Y:Y,_xlfn.SINGLE(MATCH(_xlfn.SINGLE(D:D),样品编号表!H:H,0)))) -> 精品里布 | F17: =_xlfn.SINGLE(INDEX(样品编号表!Z:Z,_xlfn.SINGLE(MATCH(_xlfn.SINGLE(D:D),样品编号表!H:H,0)))) -> 50D超柔四面弹（88克） | G17: 白色 | H17: 1 | I17: 米 | J17: 5 | K17: =H17*J17 -> 5
